Workbook

Sheet Dashboard
A1: 교보문고 실시간 베스트셀러 분석 대시보드
A3: 총 도서 수 | D3: 평균 정가 | G3: 평균 평점 | J3: 총 리뷰 수
A4: =COUNTA(RawData!C2:C100) | D4: =AVERAGE(RawData!H2:H100) | G4: =AVERAGE(RawData!M2:M100) | J4: =SUM(RawData!L2:L100)
A6: 점유율 상위 출판사 TOP 10 | F6: 가격대별 분포 현황
A7: 출판사 | B7: 도서건수 | C7: 평균평점 | D7: 총리뷰건수 | F7: 가격구간 | G7: 도서건수 | H7: 평균평점
A8: =Analysis!A2 | B8: =Analysis!B2 | C8: =Analysis!C2 | D8: =Analysis!D2 | F8: =Analysis!H2 | G8: =Analysis!I2 | H8: =Analysis!J2
A9: =Analysis!A3 | B9: =Analysis!B3 | C9: =Analysis!C3 | D9: =Analysis!D3 | F9: =Analysis!H3 | G9: =Analysis!I3 | H9: =Analysis!J3
A10: =Analysis!A4 | B10: =Analysis!B4 | C10: =Analysis!C4 | D10: =Analysis!D4 | F10: =Analysis!H4 | G10: =Analysis!I4 | H10: =Analysis!J4
A11: =Analysis!A5 | B11: =Analysis!B5 | C11: =Analysis!C5 | D11: =Analysis!D5 | F11: =Analysis!H5 | G11: =Analysis!I5 | H11: =Analysis!J5
A12: =Analysis!A6 | B12: =Analysis!B6 | C12: =Analysis!C6 | D12: =Analysis!D6 | F12: =Analysis!H6 | G12: =Analysis!I6 | H12: =Analysis!J6
A13: =Analysis!A7 | B13: =Analysis!B7 | C13: =Analysis!C7 | D13: =Analysis!D7 | F13: =Analysis!H7 | G13: =Analysis!I7 | H13: =Analysis!J7
A14: =Analysis!A8 | B14: =Analysis!B8 | C14: =Analysis!C8 | D14: =Analysis!D8
A15: =Analysis!A9 | B15: =Analysis!B9 | C15: =Analysis!C9 | D15: =Analysis!D9
A16: =Analysis!A10 | B16: =Analysis!B10 | C16: =Analysis!C10 | D16: =Analysis!D10
A17: =Analysis!A11 | B17: =Analysis!B11 | C17: =Analysis!C11 | D17: =Analysis!D11

Sheet Analysis
A1: 출판사 | B1: 도서건수 | C1: 평균평점 | D1: 총리뷰건수 | F1: 구간하한 | G1: 구간상한 | H1: 가격구간 | I1: 도서건수 | J1: 평균평점 | L1: 평점하한 | M1: 평점상한 | N1: 평점구간 | O1: 도서건수 | P1: 평균리뷰수
A2: 한국교육방송공사(EBSi) | B2: =COUNTIF(RawData!$F$2:$F$100, A2) | C2: =AVERAGEIF(RawData!$F$2:$F$100, A2, RawData!$M$2:$M$100) | D2: =SUMIF(RawData!$F$2:$F$100, A2, RawData!$L$2:$L$100) | F2: 0 | G2: 10000 | H2: 1만원 이하 | I2: =COUNTIFS(RawData!$I$2:$I$100, ">="&F2, RawData!$I$2:$I$100, "<"&G2) | J2: =AVERAGEIFS(RawData!$M$2:$M$100, RawData!$I$2:$I$100, ">="&F2, RawData!$I$2:$I$100, "<"&G2) | L2: 0 | M2: 8 | N2: 8.0 이하 | O2: =COUNTIFS(RawData!$M$2:$M$100, ">="&L2, RawData!$M$2:$M$100, "<"&M2) | P2: =AVERAGEIFS(RawData!$L$2:$L$100, RawData!$M$2:$M$100, ">="&L2, RawData!$M$2:$M$100, "<"&M2)
A3: 민음사 | B3: =COUNTIF(RawData!$F$2:$F$100, A3) | C3: =AVERAGEIF(RawData!$F$2:$F$100, A3, RawData!$M$2:$M$100) | D3: =SUMIF(RawData!$F$2:$F$100, A3, RawData!$L$2:$L$100) | F3: 10000 | G3: 15000 | H3: 1만~1.5만원 | I3: =COUNTIFS(RawData!$I$2:$I$100, ">="&F3, RawData!$I$2:$I$100, "<"&G3) | J3: =AVERAGEIFS(RawData!$M$2:$M$100, RawData!$I$2:$I$100, ">="&F3, RawData!$I$2:$I$100, "<"&G3) | L3: 8 | M3: 9 | N3: 8.0 초과~9.0 | O3: =COUNTIFS(RawData!$M$2:$M$100, ">="&L3, RawData!$M$2:$M$100, "<"&M3) | P3: =AVERAGEIFS(RawData!$L$2:$L$100, RawData!$M$2:$M$100, ">="&L3, RawData!$M$2:$M$100, "<"&M3)
A4: 이투스북 | B4: =COUNTIF(RawData!$F$2:$F$100, A4) | C4: =AVERAGEIF(RawData!$F$2:$F$100, A4, RawData!$M$2:$M$100) | D4: =SUMIF(RawData!$F$2:$F$100, A4, RawData!$L$2:$L$100) | F4: 15000 | G4: 20000 | H4: 1.5만~2만원 | I4: =COUNTIFS(RawData!$I$2:$I$100, ">="&F4, RawData!$I$2:$I$100, "<"&G4) | J4: =AVERAGEIFS(RawData!$M$2:$M$100, RawData!$I$2:$I$100, ">="&F4, RawData!$I$2:$I$100, "<"&G4) | L4: 9 | M4: 9.5 | N4: 9.0 초과~9.5 | O4: =COUNTIFS(RawData!$M$2:$M$100, ">="&L4, RawData!$M$2:$M$100, "<"&M4) | P4: =AVERAGEIFS(RawData!$L$2:$L$100, RawData!$M$2:$M$100, ">="&L4, RawData!$M$2:$M$100, "<"&M4)
A5: 두산매거진 | B5: =COUNTIF(RawData!$F$2:$F$100, A5) | C5: =AVERAGEIF(RawData!$F$2:$F$100, A5, RawData!$M$2:$M$100) | D5: =SUMIF(RawData!$F$2:$F$100, A5, RawData!$L$2:$L$100) | F5: 20000 | G5: 25000 | H5: 2만~2.5만원 | I5: =COUNTIFS(RawData!$I$2:$I$100, ">="&F5, RawData!$I$2:$I$100, "<"&G5) | J5: =AVERAGEIFS(RawData!$M$2:$M$100, RawData!$I$2:$I$100, ">="&F5, RawData!$I$2:$I$100, "<"&G5) | L5: 9.5 | M5: 10.1 | N5: 9.5 초과 | O5: =COUNTIFS(RawData!$M$2:$M$100, ">="&L5, RawData!$M$2:$M$100, "<"&M5) | P5: =AVERAGEIFS(RawData!$L$2:$L$100, RawData!$M$2:$M$100, ">="&L5, RawData!$M$2:$M$100, "<"&M5)
A6: 생각의길 | B6: =COUNTIF(RawData!$F$2:$F$100, A6) | C6: =AVERAGEIF(RawData!$F$2:$F$100, A6, RawData!$M$2:$M$100) | D6: =SUMIF(RawData!$F$2:$F$100, A6, RawData!$L$2:$L$100) | F6: 25000 | G6: 30000 | H6: 2.5만~3만원 | I6: =COUNTIFS(RawData!$I$2:$I$100, ">="&F6, RawData!$I$2:$I$100, "<"&G6) | J6: =AVERAGEIFS(RawData!$M$2:$M$100, RawData!$I$2:$I$100, ">="&F6, RawData!$I$2:$I$100, "<"&G6)
A7: 비상교육 | B7: =COUNTIF(RawData!$F$2:$F$100, A7) | C7: =AVERAGEIF(RawData!$F$2:$F$100, A7, RawData!$M$2:$M$100) | D7: =SUMIF(RawData!$F$2:$F$100, A7, RawData!$L$2:$L$100) | F7: 30000 | G7: 999999 | H7: 3만원 초과 | I7: =COUNTIFS(RawData!$I$2:$I$100, ">="&F7, RawData!$I$2:$I$100, "<"&G7) | J7: =AVERAGEIFS(RawData!$M$2:$M$100, RawData!$I$2:$I$100, ">="&F7, RawData!$I$2:$I$100, "<"&G7)
A8: 더페이지 | B8: =COUNTIF(RawData!$F$2:$F$100, A8) | C8: =AVERAGEIF(RawData!$F$2:$F$100, A8, RawData!$M$2:$M$100) | D8: =SUMIF(RawData!$F$2:$F$100, A8, RawData!$L$2:$L$100)
A9: 허스트중앙 | B9: =COUNTIF(RawData!$F$2:$F$100, A9) | C9: =AVERAGEIF(RawData!$F$2:$F$100, A9, RawData!$M$2:$M$100) | D9: =SUMIF(RawData!$F$2:$F$100, A9, RawData!$L$2:$L$100)
A10: 미디어숲 | B10: =COUNTIF(RawData!$F$2:$F$100, A10) | C10: =AVERAGEIF(RawData!$F$2:$F$100, A10, RawData!$M$2:$M$100) | D10: =SUMIF(RawData!$F$2:$F$100, A10, RawData!$L$2:$L$100)
A11: 어센딩 | B11: =COUNTIF(RawData!$F$2:$F$100, A11) | C11: =AVERAGEIF(RawData!$F$2:$F$100, A11, RawData!$M$2:$M$100) | D11: =SUMIF(RawData!$F$2:$F$100, A11, RawData!$L$2:$L$100)
A12: 대원씨아이 | B12: =COUNTIF(RawData!$F$2:$F$100, A12) | C12: =AVERAGEIF(RawData!$F$2:$F$100, A12, RawData!$M$2:$M$100) | D12: =SUMIF(RawData!$F$2:$F$100, A12, RawData!$L$2:$L$100)
A13: 이든서재 | B13: =COUNTIF(RawData!$F$2:$F$100, A13) | C13: =AVERAGEIF(RawData!$F$2:$F$100, A13, RawData!$M$2:$M$100) | D13: =SUMIF(RawData!$F$2:$F$100, A13, RawData!$L$2:$L$100)
A14: 문학동네 | B14: =COUNTIF(RawData!$F$2:$F$100, A14) | C14: =AVERAGEIF(RawData!$F$2:$F$100, A14, RawData!$M$2:$M$100) | D14: =SUMIF(RawData!$F$2:$F$100, A14, RawData!$L$2:$L$100)
A15: 알토북스 | B15: =COUNTIF(RawData!$F$2:$F$100, A15) | C15: =AVERAGEIF(RawData!$F$2:$F$100, A15, RawData!$M$2:$M$100) | D15: =SUMIF(RawData!$F$2:$F$100, A15, RawData!$L$2:$L$100)
A16: 북플레저 | B16: =COUNTIF(RawData!$F$2:$F$100, A16) | C16: =AVERAGEIF(RawData!$F$2:$F$100, A16, RawData!$M$2:$M$100) | D16: =SUMIF(RawData!$F$2:$F$100, A16, RawData!$L$2:$L$100)

Sheet RawData
A1: 상품번호 | B1: 순위 | C1: 도서명 | D1: 부제목 | E1: 저자 | F1: 출판사 | G1: 출판일 | H1: 정가 | I1: 할인가 | J1: 할인율 | K1: 판매지수 | L1: 리뷰건수 | M1: 평점 | N1: 태그 | O1: 이미지URL
A2: S000220574468 | B2: 1 | C2: 지큐 코리아(GQ KOREA)(2026년 8월호)(C형) | D2: 《GQ》는 영국, 독일, 이탈리아, 스페인, 러시아 등 세계 18개국의 스타일 있는 남자를 위한 지침서로서 독보적인 위치를 구축하고 있다. 하나의 이슈, 하나의 칼럼마다 담겨있는 『지큐(GQ) KOREA』의 이념과 모토는, 대한민국에서 가장 개명한 스타일을 지닌 남자 그룹뿐 아니라 좋은 취향을 지닌 똑똑한 여자들에 이르기까지 당대 가장 고급한 독자들의 지지로 익히 대변된다. | E2: 두산매거진 편집부 | F2: 두산매거진 | G2: 2026-07-27 | H2: 10000 | I2: 9500 | J2: 5 | K2: 0 | L2: 0 | M2: 0 | N2: 잡지 | O2: https://contents.kyobobook.co.kr/sih/fit-in/200x0/pdt/3904000621838.jpg
A3: S000220574458 | B3: 2 | C3: 지큐 코리아(GQ KOREA)(2026년 8월호)(A형) | D3: 《GQ》는 영국, 독일, 이탈리아, 스페인, 러시아 등 세계 18개국의 스타일 있는 남자를 위한 지침서로서 독보적인 위치를 구축하고 있다. 하나의 이슈, 하나의 칼럼마다 담겨있는 『지큐(GQ) KOREA』의 이념과 모토는, 대한민국에서 가장 개명한 스타일을 지닌 남자 그룹뿐 아니라 좋은 취향을 지닌 똑똑한 여자들에 이르기까지 당대 가장 고급한 독자들의 지지로 익히 대변된다. | E3: 두산매거진 편집부 | F3: 두산매거진 | G3: 2026-07-27 | H3: 10000 | I3: 9500 | J3: 5 | K3: 0 | L3: 0 | M3: 0 | N3: 잡지 | O3: https://contents.kyobobook.co.kr/sih/fit-in/200x0/pdt/3904000621814.jpg
A4: S000220429584 | B4: 3 | C4: 유럽 도시 기행 3 | D4: 유럽의 서쪽 끝에서 만난, 가장 인간적인 도시들 『유럽도시기행 3』은 유라시아 대륙의 서쪽 끝, 이베리아반도의 네 도시로 독자를 이끈다. 한때 세계사의 항로를 바꾼 대항해 시대의 주역이었지만, 이후 내전과 독재, 혁명과 재건을 겪으며 쇠퇴와 정체, 혼란과 회복의 시간을 통과해 온 도시들이다. 유시민 작가는 이 도시들을 빠르게 소비하기보다 거리와 광장, 미술관과 시장, 성당과 골목, 식당과 강변을 천천히 걸으며 도시가 무엇을 기억하고 사람들이 무엇을 사랑하며 오늘을 살아가는지 들여다본다. “정복 전쟁을 일삼았던 포르투갈 왕국은 대항해 시대의 짧은 전성기를 지나 유럽의 변방 국가로 되돌아왔다. 공화주의 혁명을 이룬 뒤에는 살라자르의 장기독재를 겪었다. 그런 역사를 살아온 사람이라면 이렇게 생각할 수 있을 것이다. ‘힘을 다해 이웃과 싸우면서 남을 정복했지만, 승리는 오래가지 않았고 남은 것도 없다. … 이웃을 적으로 삼기보다는 서로 기댈 수 있는 친구로 만드는 게 낫지 않겠는가. …그런 생각을 가진 사람은 붐비는 거리에서도 발걸음을 재촉하지 않는다. 친구나 사업 파트너를 만나면 차 한 잔을 앞에 두고 충분히 들으면서 오래 이야기를 나눈다. 이방인에게도 경계하고 의심하는 표정이 아니라 여유롭게 환대하는 미소를 선사한다. 리스본과 뽀르투 사람들한테서 나는 그런 마음을 느꼈다.” “규모가 작지 않지만, 모든 것이 소박한 성당이었다. 스테인드글라스는 최소한의 자연광을 받아들이는 수준이었고 설교대는 조그마했으며 홀에는 기다란 나무 의자 말고는 아무것도 없었다. 가족을 두고 위험이 넘실대는 바다로 나갔던 어부들의 마음이, 출항할 때마다 일렁거렸을 불안감이, 만선의 꿈을 이루고 회항하면서 느꼈을 안도감이 느껴졌다.” “역시 파두는 술잔을 기울이며 듣는 게 맛있었다. 오르막 골목길, 예배당 건물이었음을 짐작할 수 있는 외관, 은은하게 새어 나오는 불빛, 꾸밈없는 무대, 허세를 내뿜는 가수들의 몸짓까지 모든 것이 이국적이었다. ‘그래, 유럽 여행은 이런 맛이지.’” 작가가 들여다본 네 도시는 인간적이다. 도시의 역사가 만들어낸 영광과 몰락, 자부심과 상처, 슬픔과 유머, 결핍과 환대, 기억과 망각이 도시의 거리와 광장과 식탁 위에 고스란히 놓여있다. 이 도시들은 인간이 살아가며 겪는 거의 모든 감정을 품고 있다. 그래서 이름난 랜드마크보다 그곳 사람들의 표정, 저녁의 광장, 골목의 소음, 한 잔의 와인, 낡은 성당 안의 침묵이 작가의 마음에 더 오래 남는다. 『유럽도시기행 3』은 유시민 작가의 시선으로 포착한 유럽의 또 다른 얼굴, 가장 인간적인 도시로 우리를 안내한다. | E4: 유시민 | F4: 생각의길 | G4: 2026-07-09 | H4: 18900 | I4: 17010 | J4: 10 | K4: 0 | L4: 62 | M4: 9.93 | N4: 인문 | O4: https://contents.kyobobook.co.kr/sih/fit-in/200x0/pdt/9788965138310.jpg
A5: S000220574470 | B5: 4 | C5: 지큐 코리아(GQ KOREA)(2026년 8월호)(D형) | D5: 《GQ》는 영국, 독일, 이탈리아, 스페인, 러시아 등 세계 18개국의 스타일 있는 남자를 위한 지침서로서 독보적인 위치를 구축하고 있다. 하나의 이슈, 하나의 칼럼마다 담겨있는 『지큐(GQ) KOREA』의 이념과 모토는, 대한민국에서 가장 개명한 스타일을 지닌 남자 그룹뿐 아니라 좋은 취향을 지닌 똑똑한 여자들에 이르기까지 당대 가장 고급한 독자들의 지지로 익히 대변된다. | E5: 두산매거진 편집부 | F5: 두산매거진 | G5: 2026-07-27 | H5: 10000 | I5: 9500 | J5: 5 | K5: 0 | L5: 0 | M5: 0 | N5: 잡지 | O5: https://contents.kyobobook.co.kr/sih/fit-in/200x0/pdt/3904000621845.jpg
A6: S000220574464 | B6: 5 | C6: 지큐 코리아(GQ KOREA)(2026년 8월호)(B형) | D6: 《GQ》는 영국, 독일, 이탈리아, 스페인, 러시아 등 세계 18개국의 스타일 있는 남자를 위한 지침서로서 독보적인 위치를 구축하고 있다. 하나의 이슈, 하나의 칼럼마다 담겨있는 『지큐(GQ) KOREA』의 이념과 모토는, 대한민국에서 가장 개명한 스타일을 지닌 남자 그룹뿐 아니라 좋은 취향을 지닌 똑똑한 여자들에 이르기까지 당대 가장 고급한 독자들의 지지로 익히 대변된다. | E6: 두산매거진 편집부 | F6: 두산잡지BU | G6: 2026-07-27 | H6: 10000 | I6: 9500 | J6: 5 | K6: 0 | L6: 0 | M6: 0 | N6: 잡지 | O6: https://contents.kyobobook.co.kr/sih/fit-in/200x0/pdt/3904000621821.jpg
A7: S000220279442 | B7: 6 | C7: 니체와 함께 지적 대화를 | D7: 니체는 오늘날 철학자들 가운데 가장 많이 읽히고 인기 있는 철학자다. 대부분 ‘니체’ 하면 “신은 죽었다”라는 말이나 ‘초인(Ubermensch)’, ‘아모르 파티(Amor Fati)’를 떠올린다. 그러면서 자신도 니체 같은 생각을 하며 살아간다고 말한다. 그렇다면 과연 ‘니체 같은’ 생각이란 무엇일까? 또 니체 철학을 제대로 이해하고 실천하는 것일까? 《니체와 함께 지적 대화를》은 이러한 질문에서 비롯되었다. 사실 니체 철학은 어렵다. 지금까지 수많은 니체 철학책이 나왔고, 대중적으로도 널리 알려졌지만, 니체 특유의 문체와 비유로 인해 그 내용의 진의를 파악하기란 쉽지 않다. 이렇듯 ‘읽기 어려운’ 독자들을 위해 오랫동안 니체를 비롯한 철학을 깊이 탐구해 온 양원근 작가가 니체 철학을 삶에 녹여낸 철학책을 펼쳐냈다. 이 책은 니체 철학의 원문을 바탕으로 니체가 전하려던 핵심 메시지를 쉽게 이해하고, 자기 삶에 적용할 수 있도록 작가가 직접 경험한 사례와 깨달음을 담아냈다. 니체를 잘 모르는 독자들은 물론, 이미 니체 철학을 접한 독자들 역시 이 책을 통해 니체 철학에 대한 이해의 폭이 더 넓어져 관계와 일, 감정과 태도의 변화를 경험할 수 있다. “철학은 느리다. 하지만 빨리 가는 것보다 ‘내가 왜 그 길을 가는지’ 아는 일이 중요하다. 마찬가지로 니체를 통해 더 많은 답을 얻기보다 더 ‘깊은 질문’을 품게 되기를 바란다. 그 질문 끝에서 자기 삶을 조금 더 용기 있게, 조금 더 정직하게, 조금 더 사랑하며 살아가기를 바란다.” 양원근 작가의 말이다. 사실 우리는 남들 눈치를 보느라, 착하게 보이기 위해, 또는 실패가 두려워서 자신을 희생하거나 괴롭히는 일이 많다. 그의 말처럼 ‘깊은 질문’을 품는다면 스스로 가장 ‘깊은 답’을 찾을 수 있다. 이 책은 그저 단순히 ‘읽고 끝나는’ 철학책이 아니라, 자기 삶을 재구성하게 만드는 ‘실천하는 철학’의 안내서다. 독자들은 이 책을 통해 ‘진짜 나’를 발견하여 타인의 기준이 아닌 ‘내 삶의 주인’으로서 자아를 실현하고, 삶의 진정한 가치를 추구하게 될 것이다. 지금 삶의 고통과 괴로움에 지쳐있다면, 인생을 살아가는 이유와 목적을 몰라 혼란스럽다면, 내 인생을 ‘나답게’ 살고 싶다면 바로 니체와의 지적 대화가 필요한 순간이다. 《니체와 함께 지적 대화를》이 해결책이 되어줄 것이다. | E7: 양원근 | F7: 리미트리스 | G7: 2026-06-23 | H7: 18800 | I7: 16920 | J7: 10 | K7: 0 | L7: 67 | M7: 9.9 | N7: 인문 | O7: https://contents.kyobobook.co.kr/sih/fit-in/200x0/pdt/9791198409690.jpg
A8: S000000620195 | B8: 7 | C8: 싯다르타 | D8: 인도에서 가장 높은 계급인 브라만의 아들 싯다르타는 깨달음을 얻기 위해 아버지의 만류에도 친구 고빈다와 함께 출가한다. 그는 불교를 창시한 석가모니 수하에서 수행할 기회를 얻지만, 부처의 가르침을 통해서가 아니라 스스로 깨달음을 찾아야 한다는 것을 깨닫고는 친구 고빈다를 두고 홀로 길을 떠난다. 이후 싯다르타는 중년이 될 때까지 사랑하는 여인과 부유한 상인을 만나 세속의 욕망을 즐기다가 그에 찌든 자신을 발견하고 모든 것을 버린 채 뱃사공이 된다. 『싯다르타』는 헤세가 거의 일 년 반 동안 창작이 거의 불가능할 정도로 심한 우울증을 앓다가 정신 치료를 받은 후 발표한 작품이다. 동서양의 정신적 유산을 시적으로 승화한 일종의 종교적 성장소설로 볼 수 있는데 영원을 향한 갈망과 인간의 내면을 깊이 파고드는 초월에 대한 의지를 단순하고도 서정적인 문체로 담아냈다. 정형화된 종교 교리와 자족적인 영혼의 성찰 사이의 고뇌를 섬세하게 그리며 자아 발견을 위한 길이 하나로 정해져 있지 않음을 시사하고 철학이나 종교, 그 밖의 모든 신념에 맹목적으로 의지하고자 하는 고정관념에 도전한 작품이다. | E8: 헤르만 헤세 | F8: 민음사 | G8: 2002-01-20 | H8: 8000 | I8: 7200 | J8: 10 | K8: 0 | L8: 1533 | M8: 9.74 | N8: 소설 | O8: https://contents.kyobobook.co.kr/sih/fit-in/200x0/pdt/9788937460586.jpg
A9: S000219790863 | B9: 8 | C9: AI 이후의 미래 어떻게 될 것인가 | D9: 세계 산업 전반을 뒤흔드는 AI 운영체제, 부와 권력은 어디로 향하는가 “AI는 도구가 아니라 새로운 ‘지배 시스템’이다” AI는 아직 머나먼 미래라고 생각하는 사람들이 있다. 신기술은 늘 과장되기 마련이고, 현실화하는 데는 충분한 시간이 필요하다고 생각한다. 하지만 이런 낙관은 시대의 낙오자를 만드는 안일한 사고일 뿐이다. 인터넷이 그랬고, 스마트폰이 그랬다. 변화를 과소평가한 사람들은 늘 뒤늦게 따라붙었고, 그 사이에 기회는 이미 다른 사람들의 몫이 되었다. 지금 우리가 마주한 AI 역시 예외가 아니다. 문제는 변화의 속도가 아니라, 우리가 얼마나 빠르게 그리고 제대로 대응하느냐다. 이 책의 저자 제이슨 솅커는 AI가 불러일으키는 변화를 단순한 전망이 아니라 ‘불가피한 현실’로 다룬다. ‘블룸버그가 선정한 세계 1위 미래 전략가’라는 수식이 과장이 아닌 이유는, 데이터에 기반한 그의 분석이 실제 시장과 정책 결정의 현장에서 활용되기 때문이다. 그는 금융·에너지·고용·지정학적 리스크까지 다양한 영역에서 예측 정확도를 입증해 왔고, 미국 국방부와 중앙정보국, 글로벌 기업들을 상대로 전략 자문을 제공해 왔다. 그간의 통찰을 바탕으로 그는 미래가 실제로 어떻게 전개될지를 구체적으로 설명한다. AI는 특정 분야에서 쓰이는 도구가 아니라, 거의 모든 분야에서 기본 전제가 되는 인프라로 자리 잡고 있다. 전기나 인터넷이 그랬듯이, 한때는 혁신이었던 기술이 어느 순간 ‘당연한 것’이 되는 지점에 도달하는 것이다. 이 책이 주목하는 것은 바로 그 전환의 순간이다. AI가 경제와 산업을 움직이는 ‘보이지 않는 운영체제’가 되어 가는 과정을 짚으며, 그 전환이 개인의 커리어, 기업의 경쟁력, 국가의 전략에 어떤 영향을 미치는지를 체계적으로 풀어낸다. 특히 눈여겨볼 점은 이 책이 단순한 전망이나 가능성의 나열에 머물지 않는다는 것이다. 무엇이 바뀌는지에 대한 설명을 넘어, 그 변화 속에서 어떤 선택을 해야 하는지를 분명하게 제시한다. AI가 생산성을 어떻게 끌어올리는지, 왜 일부 직무는 빠르게 사라지고 다른 역할은 더 중요해지는지, 그리고 기업이 어떤 방향으로 전략을 수정해야 하는지를 실제 사례와 함께 보여준다. 이는 기술에 대한 이해를 넘어, 의사결정을 위한 기준을 제공한다는 점에서 다른 AI 관련 서적들과 분명히 구별된다. 이 책을 읽다 보면 자연스럽게 한 가지 질문에 이르게 된다. “이 변화가 분명하다면, 나는 어디에 서게 될 것인가?” 이미 AI를 활용해 더 높은 생산성과 성과를 만들어내는 사람들과, 여전히 변화의 바깥에서 상황을 관망하는 사람들 사이의 간극은 점점 더 벌어지고 있다. 변화는 이미 시작되었다. 이 책은 그 변화의 방향을 보여주고, 어디에서 기회를 포착해야 하는지를 명확하게 짚는다. 이제 필요한 것은 더 많은 정보가 아니라, 더 빠른 이해와 더 정확한 판단이다. 그런 의미에서 이 책은 단순히 AI를 설명하는 것이 아니라, 앞으로의 삶을 어떻게 살아갈 것인지에 대한 판단 기준을 제공한다. 그리고 그 판단을 미루는 대가는 생각보다 훨씬 클 것이다. | E9: 제이슨 솅커 | F9: 더페이지 | G9: 2026-05-10 | H9: 18800 | I9: 16920 | J9: 10 | K9: 0 | L9: 141 | M9: 9.54 | N9: 경제/경영 | O9: https://contents.kyobobook.co.kr/sih/fit-in/200x0/pdt/9791194156413.jpg
A10: S000220574443 | B10: 9 | C10: 바자(2026년 8월호) | D10: 현대 여성의 문화와 스타일- 그 속에 담긴 영감을 담다. 『바자(BAZAAR)』는 1867년 처음 선보인 이후 151년동안 고유의 정체성을 지켜오며 아름답고 예술적인 뮤즈와 비교할 수 없는 특유의 스타일로 현대 여성들의 문화와 스타일을 제공해왔다. | E10: 허스트중앙 편집부 | F10: 허스트중앙 | G10: 2026-07-23 | H10: 7000 | I10: 6650 | J10: 5 | K10: 0 | L10: 0 | M10: 0 | N10: 잡지 | O10: https://contents.kyobobook.co.kr/sih/fit-in/200x0/pdt/3904000621784.jpg
A11: S000220447871 | B11: 10 | C11: 공부 천재들의 남다른 AI 활용법 | D11: 요즘 교실 풍경은 생성형 AI의 출시 전과 후로 완전히 달라졌다. 학생들은 수행 평가가 시작되면 스마트폰과 태블릿 PC부터 켠다. 모르는 내용은 검색하고, 발표 자료는 캔바로 만들고, ChatGPT에게 발표 대본을 물어본다. 안타깝게도 대부분의 학생이 AI를 ‘대신 답을 찾아 주는 기계’로 사용하는 것이 현실이다. 그렇게 쓰면 숙제를 끝내도 자신의 실력은 전혀 늘지 않는다. 오히려 AI에게 공부할 기회를 빼앗기는 셈이다. 다 같이 AI를 쓰는데도 실력이 갈리는 이유다. 무엇을, 어떻게, 어디까지 써야 하는지 모르면 AI는 오히려 내 공부를 망치는 지름길이 된다. 이 책은 학교 현장에서 학생들을 직접 지도하며 검증한 중고등학생 맞춤 AI 활용법을 담았다. 수행 평가와 진로 상담, 학생부 관리와 학습 코칭을 해 온 현직 교사가 ‘지금 학생들에게 정말 필요한 전략은 무엇인가’를 고민한 끝에 찾아낸 가장 실용적이고 현실적인 로드맵이다. PPT를 어떻게 만들어야 할지 몰라 막막해하는 학생에게는 캔바(Canva)로 발표 자료를 빠르게 구성하는 방법을 알려 주고, ChatGPT를 단순 대답 생성기가 아닌 ‘보조 교사’처럼 활용하는 질문법을 설명한다. 발표 시간마다 고개를 숙인 채 화면만 읽는 학생에게는 청중과 눈을 맞추는 기술을 알려 주고, 조별 과제의 문제를 해결하기 위한 협업 시스템까지 제안한다. 여기서 끝나지 않는다. 수행 평가 결과물을 단순 제출용 과제가 아닌 학생부와 연결하여 디지털 포트폴리오로 확장하는 방법, 유튜브 시청 기록과 SNS를 통해 자신의 진로를 찾는 단서를 발견하는 방법까지 제공한다. 수행 평가, 발표, 학생부, 진로 설계까지 하나의 흐름으로 연결되면서 ‘과제 잘하는 법’을 넘어 ‘자기만의 공부 시스템을 만드는 법’을 익힐 수 있다. 이제 AI를 쓸지 말지를 고민하는 단계는 지났다. 중요한 것은 ‘얼마나 잘 활용하느냐’다. 제대로 활용한 AI는 단순히 답을 대신 찾아 주는 도구가 아니라, 생각의 폭과 깊이를 넓혀 주는 나만의 공부 도구가 된다. 이제 공부는 오래 앉아 있는 학생보다 디지털 도구를 똑똑하게 활용하는 학생이 앞서가는 시대가 되었다. 이 책은 그 차이를 만드는 가장 현실적인 AI 활용법을 담았다. | E11: 이보미 | F11: 미디어숲 | G11: 2026-07-20 | H11: 17800 | I11: 16020 | J11: 10 | K11: 0 | L11: 7 | M11: 10 | N11: 청소년 | O11: https://contents.kyobobook.co.kr/sih/fit-in/200x0/pdt/9791158749361.jpg
A12: S000220500994 | B12: 11 | C12: 어떻게 살아낼 것인가 | D12: 10년에 걸친 연구, 34명의 삶, 총 2,809년의 생애 데이터로 밝혀낸 인생의 전환기를 통과하는 법 커리어의 정체, 번아웃, 은퇴, 상실… 삶의 전환기를 통과하는 모든 이들을 위한 책 20년간 아마존 경제경영 베스트셀러에 오른 《좋은 기업을 넘어 위대한 기업으로》의 저자 짐 콜린스가 신작 《어떻게 살아낼 것인가》로 돌아왔다. 세계적인 경영학자이자 비즈니스 구루인 그는 지난 30여 년간 위대한 기업과 리더의 조건을 연구하며 수많은 독자들에게 깊은 영향을 미쳐왔다. 그런 짐 콜린스가 이번에는 기업이 아닌 '인간의 삶' 자체를 연구 대상으로 삼았다. 그는 10년에 걸쳐 34명의 삶, 총 2,809년에 이르는 압도적인 생애 데이터를 추적하며 한 가지 질문에 몰두했다. 삶이 무너진 뒤, 사람은 어떻게 다시 자신을 만들어가는가. 《어떻게 살아낼 것인가》는 단순히 성공의 공식을 말하는 책이 아니다. 오히려 성공과 실패를 동시에 바라보며 누구나 삶에서 반복적으로 마주하게 되는 인생의 전환기를 어떻게 통과할 것인지를 탐구하는 인생 재건서다. 저자는 성공을 유지한 인물과 좌절 이후 다시 일어선 사람들의 생애를 깊이 분석하며, 삶의 위기 앞에서 자신을 재생시키는 공통의 원칙들을 발견해낸다. 성공했던 록 뮤지션, 명성을 잃은 공인, 목표를 달성한 운동선수와 사회운동가 등 다양한 인물들의 삶을 비교 분석하며, 인간은 어떻게 다시 삶의 방향을 찾고 새로운 의미를 만들어가는지를 보여준다. 성공 공식을 제시하는 대신, 무너진 뒤에도 다시 삶을 만들어가는 힘을 이야기한다는 점에서 기존 자기계발서와는 결이 다르다. 특히 이번 책은 짐 콜린스가 처음으로 자신의 이야기를 깊이 있게 풀어낸 책이라는 점에서도 의미가 크다. 그는 이 프로젝트를 통해 자신의 사고방식과 감정, 삶을 바라보는 태도까지 근본적으로 변화했다고 고백한다. “삶을 어떻게 만들어갈 것인가.” 이 질문에서 출발한 이 책은 결국 삶의 방향과 자기 이해에 관한 가장 본질적인 통찰로 이어진다. 오랫동안 위대한 기업의 조건을 연구해온 저자가 이제는 오래 살아남는 삶의 조건을 이야기한다는 점에서, 《어떻게 살아낼 것인가》는 짐 콜린스 사상의 새로운 전환점이자 완결편이라 할 수 있다. | E12: 짐 콜린스 | F12: 필름(Feelm) | G12: 2026-07-15 | H12: 29800 | I12: 26820 | J12: 10 | K12: 0 | L12: 12 | M12: 10 | N12: 자기계발 | O12: https://contents.kyobobook.co.kr/sih/fit-in/200x0/pdt/9791124468272.jpg
A13: S000220342712 | B13: 12 | C13: 부자들은 절대 속지 않는 돈의 함정 | D13: 매일 가계부를 쓰고 최저가를 검색하며 허리띠를 졸라매는데도 어쩐지 통장 잔고는 늘 제자리걸음이다. 이는 단순히 당신의 의지가 부족하거나 운이 없어서가 아니다. 우리는 흔히 돈을 아끼는 것이 곧 부로 가는 지름길이라 믿으며 살아간다. 하지만 역설적으로 그 절약에 대한 강박이 오히려 우리의 소중한 재산을 소리 없이 갉아먹는 주범이 되기도 한다. 할인쿠폰을 사용하기 위해 굳이 필요 없는 물건을 장바구니에 더 담거나, 당장의 지출을 줄이려다 미래의 더 큰 수익을 가져다줄 ‘기회’라는 자산을 놓치는 순간, 당신의 돈은 눈에 보이지 않는 미세한 균열을 일으키며 끊임없이 빠져나가게 된다. 이런 현상이 반복되는 근본적인 이유는 돈이 움직이는 세상의 원리를 읽어 내는 ‘인지의 힘’을 충분히 기르지 못했기 때문이다. 저자는 이 책에서 우리가 벌 수 있는 돈은 결국 자신의 ‘인지 수준’에 대한 보상이라고 말한다. 우연히 큰돈을 손에 넣더라도 그 부를 담아낼 인지적 그릇이 준비되어 있지 않다면, 자산은 결국 다시 원래의 수준으로 돌아가게 된다는 것이다. 이는 단순한 재테크 기술보다 돈을 바라보는 인식과 판단력이 훨씬 중요하다는 사실을 보여 준다. 재테크의 성패는 얼마나 많이 저축하느냐보다 가치와 가격의 차이를 구분하고, 잘못된 선택에서 얼마나 빠르게 벗어날 수 있는가에 달려 있다. 예를 들어, 직장과 가까운 곳 대신 더 저렴한 외곽 지역의 집을 선택하는 것은 당장 돈을 절약하는 것처럼 보일 수 있다. 그러나 매일 출퇴근에 소비되는 시간과 에너지, 그리고 그 시간을 자기 계발이나 새로운 기회에 투자했을 때 얻을 수 있는 가능성까지 함께 고려한다면, 그것은 또 다른 형태의 손실이 될 수도 있다. 저자는 이처럼 우리가 일상에서 반복하는 경제적 판단 착오를 확률과 게임 이론, 행동경제학의 관점에서 풀어내며 독자 스스로 자신의 ‘인생 장부’를 다시 점검하도록 이끈다. 열심히 벌고 아끼는데도 왜 돈이 모이지 않는지 궁금했다면, 이 책은 그 이유를 새로운 시각으로 보여 줄 것이다. 경제학과 금융의 기본 원리를 통해 세상이 움직이는 방식을 이해하고, 그 흐름 속에서 자산을 지키고 키워 나갈 수 있는 현실적인 사고의 기준을 얻게 될 것이다. | E13: 셰종보 | F13: 더페이지 | G13: 2026-07-20 | H13: 18800 | I13: 16920 | J13: 10 | K13: 0 | L13: 3 | M13: 10 | N13: 자기계발 | O13: https://contents.kyobobook.co.kr/sih/fit-in/200x0/pdt/9791194156437.jpg
... A18: S000220279880 | B18: 17 | C18: 사람 보는 눈이 없는 당신에게 | D18: “누구와 함께할 것인가” 애착 · 성격 · 투사 · 행동 신호로 관계가 어려워지는 심리를 짚고, 더 이상 상처받지 않기 위한 ‘나와 맞는 사람’ 찾는 법 100만 팔로워와 누적 조회 수 1억 회를 돌파한 심리 콘텐츠 크리에이터 ‘과즙너구리’의 기대작! 사람을 대하는 일은 언제나 어렵지만, 특히 ‘좋은 사람’인 줄 알았던 이에게 전혀 예상치 못한 상처를 입었을 때의 충격은 단순히 감정의 문제를 넘어 삶을 뿌리째 흔들곤 한다. 우리는 흔히 이런 일을 겪을 때 자신의 운을 탓하거나 사람 보는 눈이 없음을 자책하곤 한다. 하지만 인간관계에서 반복되는 실패는 당신의 인격이나 운의 문제가 아니다. 인간의 심리적 기제를 파악하는 ‘안목’이라는 기술을 배우지 못한 결과에 가깝다. 이러한 관계의 악순환을 끊어내려면 막연한 조언이 아니라 상대를 선명하게 들여다볼 수 있는 고해상도의 렌즈가 필요하다. 그리고 바로 그 렌즈를 제공하는 이가 중국 최고의 지식 공유 플랫폼에서 수백만 독자의 인간관계를 상담해 온 실전 심리전문가 궈즈리다. 그녀가 수천 시간의 상담과 방대한 데이터 속에서 길어 올린 결론은 분명하다. 우리가 누군가를 오해하고 상처받는 이유는, 겉모습 뒤에 숨겨진 그 사람의 심리적 설계도를 읽지 못했기 때문이다. 이 책은 이 복잡한 인간관계의 메커니즘을 애착 이론과 성격 분석, 그리고 투사 심리학을 결합한 5단계 사람 읽는 공식으로 알려준다. 애착 유형을 통해 관계의 출발점에서 이미 나타나는 차이를 읽고, 성격 구조를 통해 반복되는 행동의 방향을 파악하며, 투사라는 개념을 통해 상대가 드러내는 감정이 무엇을 의미하는지 해석한다. 여기에 더해 눈동자나 몸짓 같은 비언어적 신호를 통해 말로 설명되지 않는 부분까지 읽어낼 수 있도록 돕는다. 상대를 읽고 이해하는 안목이 생기면 자연스레 곁에 둘 사람과 거리를 두어야 할 사람을 가려내는 선별의 기준이 서고, 이는 곧 타인의 기분에 휩쓸리지 않고 자신의 일상을 온전히 지켜내는 힘으로 이어진다. 이 책은 50건 이상의 실제 사례와 10가지 이상의 자기 평가 도구를 담아, 모호한 이론이 아닌 삶에 바로 적용할 수 있는 구체적인 방법을 제시한다. 사람의 마음을 이해하는 일은 생각보다 어렵지 않다. 중요한 것은, 그 마음에 다가가는 올바른 방법을 아는 것이다. 사람에게 상처받지 않는 길은 그 사람의 실체를 정확히 읽어내고, 내가 감당할 수 있는 만큼의 경계를 분명히 세우는 안목을 갖추는 데 있다. 이 책은 그 단순하지만 단단한 원칙을 전한다. 이제 자책을 멈추고 이 정교한 심리 공식을 손에 쥔다면, 관계 갈등으로 더 이상 상처받는 사람이 아니라 관계의 흐름을 읽는 관찰자로서 흔들림 없이 삶을 지켜낼 수 있을 것이다. | E18: 궈즈리 | F18: 지니의서재 | G18: 2026-07-10 | H18: 18800 | I18: 16920 | J18: 10 | K18: 0 | L18: 6 | M18: 10 | N18: 자기계발 | O18: https://contents.kyobobook.co.kr/sih/fit-in/200x0/pdt/9791194620365.jpg
A19: S000220573912 | B19: 18 | C19: 황천의 츠가이: 봉 11(특별판) | E19: Hiromu Arakawa | F19: 대원씨아이 | G19: 2026-07-31 | H19: 28500 | I19: 25650 | J19: 10 | K19: 0 | L19: 0 | M19: 0 | N19: 만화 | O19: https://contents.kyobobook.co.kr/sih/fit-in/200x0/pdt/9791142358784.jpg
A20: S000220273403 | B20: 19 | C20: 공부가 즐겁다는 공자의 말을 믿어도 될까 | D20: 공부와 인간관계 등으로 인해 급속도로 고민이 많아지는 청소년기. 하지만 자아 성장에 있어 그 어느 때보다 중요한 이 시기에 사회는 빠르게 변화하고 있고 친구도, 부모도, 선생님도 청소년의 고민에 시원하게 대답해 주지 않는다. 그럴 때 『논어』야 말로 최고의 동반자가 되어 줄 수 있다. ‘내가 어떤 성격의 사람인지, 다른 사람들은 어떤 생각을 하며 사는지, 이 세상은 어떻게 돌아가는지’ 잘 이해할 수 있게 하는 책이기 때문이다. 『논어』는 ‘말을 편집했다’는 뜻을 지니고 있다. 공자와 그 제자들의 대화와 삶을 대하는 자세, 태도를 편집하고 기록한 책이기 때문이다. 그런데 왜 21세기를 살아가는 우리가 2천5백 년 전 이들의 대화를 주목해야 할까? 이 질문에 답하기 위해, 베스트셀러 작가인 판덩은 청소년의 눈높이에 맞춰서 공자의 삶과 지혜를 흥미롭게 풀어낸 책 『공부가 즐겁다는 공자의 말을 믿어도 될까』를 집필했다. 『논어』는 2천5백 년 전에 쓰였지만, 현재도 우리 삶에 많은 가르침을 주고 있다. 특히 『논어』에는 학습에 대한 심오하고도 진지한 고민이 엿보인다. 늘 무언가를 고민하고, 하루를 복기하며, 더 나은 내일을 위해 배우려는 공자의 자세는 AI와 양자 혁명 등 빠르게 변화하는 시대를 살아가는 현대인이 반드시 갖춰야 할 태도이다. 그런데 이는 단순히 인생 공부에만 국한되는 것이 아니다. 하루하루 학습에 매진해야 하는 청소년에게도 해당하는 태도이다. ‘공부’는 단순하고 얄팍하게 참고서나 문제집만 풀이하고 이해하는 것이 아니라, 진짜 우리의 삶과 연결성을 지녀야 한다. 실생활에 적용할 수 있는 학문이야말로 ‘살아 있는’ 학문인 것이다. 따라서 이 책 『공부가 즐겁다는 공자의 말을 믿어도 될까』의 핵심 내용은 ‘배움’이다. 하지만 여기서 배움은 단순히 책을 읽고 읊는 배움이 아니라 공부나 친구 관계, 인격이나 일상 모든 것에 대한 배움이다. 이것이야말로 공자가 강조했던 ‘일이관지(一以貫之)’, 즉 한 가지 이치로 모든 일을 꿰뚫어 본다는 진리를 구현하게 하는 것이다. 따라서 이 책은 친구 관계로 일상생활을, 일상생활로 사람의 성격을, 개인의 성격과 인격으로 삶을 통찰하게 돕는다. 흔들리는 청소년 시기에 무엇을 기준으로 세상을 살아가고 어떤 의미를 찾아 행복한 삶을 만들어 가야 할지, 그 길을 제시한다. | E20: 판덩 | F20: 이든서재 | G20: 2026-07-10 | H20: 18500 | I20: 16650 | J20: 10 | K20: 0 | L20: 6 | M20: 10 | N20: 청소년 | O20: https://contents.kyobobook.co.kr/sih/fit-in/200x0/pdt/9791194812258.jpg
A21: S000220340903 | B21: 20 | C21: 코스모스(100만부 기념판) | D21: 칼 세이건(Carl Sagan)의 「코스모스(Cosmos)」가 2026년 4월 말일 기준으로 누적 판매 부수 100만 부를 돌파했다. 2004년 고(故) 홍승수 서울대 천문학과 교수의 번역으로 양장본의 완전판이 출간된 지 22년 만에, 그리고 2006년 칼 세이건 서거 10주기를 기념해 특별판이 출간된 지 20년 만에 금자탑을 세운 것이다. 720쪽이 넘는 방대한 분량의 벽돌책이 밀리언셀러를 기록한 것은 대한민국 출판 역사상 아주 드문 사건이다. 「코스모스」 100만 부 돌파는 여러 판본의 판매를 합산한 것이다. 이 부수는 먼저 1980년에 출간된 원서의 도판을 빠짐없이 오롯이 실은, 2004년 12월 20일에 출간된 「사이언스 클래식」 4권 양장본 완전판 11만 5000부, 그다음 2006년 12월 20일에 「칼 세이건 서거 10기 특별판」으로 출간된 반양장본 보급판 87만 6000부, 그리고 전자책 3만 8000부와 진중문고판 1만 3000부 등으로 이루어져 있다. 반양장본에서 고급 양장본까지, 전자책에서 군납 도서까지 다양한 판본과 다양한 가격대로 출간된 이 책이 밀리언셀러의 고지를 밟았다는 것은 우리 사회의 과학 교양, 또는 소양이 특정 계층, 특정 연령대에 한정되어 있지 않고 종합적으로 성숙했음을 보여 주는 기념비적인 지표라고 볼 수 있다. 특히 일론 머스크 등 칼 세이건의 책과 다큐멘터리를 보고 자란 ‘코스모스 세대’가 새로운 우주 개척의 시대에 나서고 있는 지금, 「코스모스」는 다시금 주목을 받고 있다. 2020년 앤 드루얀이 「코스모스」의 정식 후속작이라고 할 「코스모스: 가능한 세계들(Cosmos: Possible Worlds)」을 출간하고, 동명의 다큐멘터리가 내셔널 지오그래픽 채널과 디즈니플러스 OTT 서비스로 전 세계 172개국에서 방영되어 칼 세이건의 「코스모스」의 정신이 죽지 않았음을 입증했다. (이 책의 한국어판은 누적 5만 3000부 판매되었다.) 또한 유튜브를 비롯한 뉴미디어 플랫폼에서도 수많은 과학 교양 채널과 도서 소개 프로그램에서 가치가 재조명되고 있다. 스타 과학자들과 인플루언서 북튜버 들에 의해 “인간으로서의 존엄과 지적 교양을 갖추기 위해 반드시 통과해야 할 관문”, 혹은 “교양인이라면 죽기 전에 꼭 넘어야 할 산”, 혹은 “우주 앞에서 인간이 얼마나 겸손하면서도 존엄한 존재인지 깨닫게 하는 책” 등의 말로 적극 추천받고 있고, AI 시대 도래 이후 넘치는 AI 생성 텍스트에 지친 20, 30대 독자들에 의해 폭발적으로 재발견되고 있다. 그 결과인지 2025년 동기 대비 판매 부수가 25퍼센트 이상 증가하고 있다. ㈜사이언스북스에서는 이번 「코스모스」 누적 판매 부수 100만 부 돌파를 기념해 표지를 교체한 리커버판 「코스모스: 100만 부 기념판」을 출간한다. 기존에 출간되던 반양장본의 표지를 1980년 칼 세이건의 다큐멘터리가 방영되던 당시 미국에서 출간되었던 랜덤하우스 출간 초판본의 표지로 교체한 것인데, 앞표지의 그림은 「코스모스」의 책과 다큐멘터리 곳곳을 장식하고 있는 천문 우주 일러스트레이션의 대가 아돌프 샬러(Adolf Schaller, 1956∼2024년)의 작품이고, 뒤표지의 사진은 다큐멘터리 출연 당시 칼 세이건의 사진이다. 본문 내용은 기존의 반양장본 특별판과 다름이 없지만, 이 원서 초판본 표지를 기억하는 눈 밝은 독자나, 아돌프 샬러가 그린 그림이 1980년 당시 인류가 상상할 수 있었던 가장 먼 천체 중 하나인 구상 성단의 퀘이사를 그린 것임을 알아채는 과학 소양 풍부한 독자라면 이 「코스모스: 100만 부 기념판」의 소장 가치와 추천 가치를 알아볼 것이다. 이 책은 2026년 6월 24일부터 개최되는 2026 서울 국제 도서전에서 서점보다 먼저 최초 공개, 판매된다. 올해 창립 60주년을 맞이한 민음사 출판 그룹의 부스에 마련된 ㈜사이언스북스 코너에서 이 책을 가장 먼저 만나 볼 수 있으며, ㈜사이언스북스 코너를 찾아 주는 독자들을 위해 매일 선착순 100명을 대상으로 이 기념판의 표지를 활용한 엘홀더를 증정한다. 공식적인 서점 판매는 주요 서점별 굿즈 이벤트와 함께 이번 달 말일부터 이루어질 예정이다. 그리고 올해는 칼 세이건의 서거 30주기이기도 하다. 이에 ㈜사이언스북스에서는 다채로운 출판 기획을 준비 중에 있다. 자세한 정보는 추후 공개할 예정이다. | E21: 칼 세이건 | F21: 사이언스북스 | G21: 2026-06-30 | H21: 22000 | I21: 19800 | J21: 10 | K21: 0 | L21: 31 | M21: 10 | N21: 과학 | O21: https://contents.kyobobook.co.kr/sih/fit-in/200x0/pdt/9791124336083.jpg
A22: S000219813471 | B22: 21 | C22: 완자 고등 물질과 에너지(2026) | D22: - 2022개정 교육과정의 4종 교과서를 완벽 분석하여 물질과 에너지의 핵심 개념을 쉽고 체계적으로 정리하였습니다. - 혼자서도 교과 개념을 익히고 내신 시험을 준비할 수 있는 ‘완벽한 자율 학습서’입니다. - 고난도 문제로 내신 1등급에 도전할 수 있습니다. | E22: 이성학 외 | F22: 비상교육 | G22: 2026-05-01 | H22: 20000 | I22: 18000 | J22: 10 | K22: 0 | L22: 32 | M22: 9.6 | N22: 중/고등참고서 | O22: https://contents.kyobobook.co.kr/sih/fit-in/200x0/pdt/9791173167980.jpg
A23: S000218781780 | B23: 22 | C23: 2026 큰별쌤 최태성의 별별한국사 기출 500제 한국사능력검정시험 심화(1,2,3급) | D23: 〈2026 큰별쌤 최태성의 별별한국사 기출 500제 한국사능력검정시험 심화(1,2,3급)〉는 2025년 76회 시험부터 2023년 67회 시험까지 최신 기출문제 10회분, 총 500문항으로 구성되었습니다. '기출 BOOK'은 실제 시험지를 그대로 구현하여 실전과 같은 문제풀이가 가능하며, '해설 BOOK'은 모든 선택지의 자세한 해설뿐만 아니라 기출 선택지와 핵심 내용도 수록하여 중요 개념을 반복적으로 학습할 수 있어 한 권으로 기출문제 풀이뿐만 아니라 개념까지 다질 수 있습니다. ▣ 제시된 이미지는 책의 뒤표지입니다. 〈2026 큰별쌤 최태성의 별별한국사 기출 500제 한국사능력검정시험 심화(1,2,3급)〉의 앞표지는 1억원 기부를 통해 사랑의 열매 '아너 소사이어티'에 가입되도록 함께 지원해 주신 최태성 1, 2TV 별님들로 구성되었습니다. | E23: 최태성 | F23: 이투스북 | G23: 2025-12-16 | H23: 22000 | I23: 19800 | J23: 10 | K23: 0 | L23: 249 | M23: 9.95 | N23: 인문 | O23: https://contents.kyobobook.co.kr/sih/fit-in/200x0/pdt/9791138934459.jpg
A24: S000216796615 | B24: 23 | C24: 안녕이라 그랬어(집에디션 리커버) | D24: 소설가 김애란이 『바깥은 여름』(문학동네, 2017) 이후 팔 년 만에 새 소설집으로 돌아왔다. “사회적 공간 속을 떠다니는 감정의 입자를 포착하고 그것에 명료한 표현을 부여하는 특유의 능력을 예리하게 발휘한 소설”이라는 평과 함께 2022 김승옥문학상 우수상을 수상한 「홈 파티」와 2022 오영수문학상 수상작인 「좋은 이웃」을 비롯해 총 일곱 편의 단편이 수록된 『안녕이라 그랬어』는 강력한 정서적 호소력과 딜레마적 물음으로 한 세계를 중층적으로 쌓아올리는 특장이 여전히 발휘되는 가운데, 이전보다 조금은 서늘하고 비정해진 김애란을 만날 수 있다. 이번 소설집의 주인공은 ‘공간’이라고도 할 수 있다. “많은 희곡 속 사건은 ‘초대’와 ‘방문’, ‘침입’과 ‘도주’로 시작됐다”(「홈 파티」, 42쪽)라는 소설 속 표현처럼, 이번 책에서는 인물들이 누군가의 공간을 방문하면서 이야기가 펼쳐진다. 그곳은 집주인의 미감과 여유를 짐작하게 하는 우아하고 안정적인 공간이거나(「홈 파티」), 값싼 물가와 저렴한 체류 비용 덕분에 한 달 여행이라는 “생애 처음으로 누리는 사치”를 가능하게 하는 해외의 단독주택이다(「숲속 작은 집」). 또는 정성스레 가꾸고 사용해왔지만 이제는 새 집주인을 위해 이사 준비를 해야 하는 전셋집이거나(「좋은 이웃」), 회사를 관두고 그간 모은 돈을 전부 털어 문을 연 책방이기도 하다(「레몬케이크」). 『안녕이라 그랬어』에서 공간이 중요한 이유는 그곳이 단순히 이야기의 배경으로 기능하는 게 아니라 인물들의 삶 그 자체와 같기 때문이다. 특히 우리 사회에서 ‘방 한 칸’이 가지는 의미를 남다른 통찰력으로 묘사해온 바 있는 김애란에게 어떤 공간은 누군가의 경제적, 사회적 지표를 가늠하게 하는 장소이자 한 사람의 내력이 고스란히 담긴 총체적이고 복합적인 장소이다. 때문에 이번 소설집에서 공간을 둘러싸고 벌어지는 갈등은 서로의 삶의 기준이 맞부딪치는 일이라고 할 수 있다. 다른 사람의 공간으로 들어가는 것은, 달리 말하면 나로 살아온 삶의 테두리를 벗어나는 사건인 것이다. 김애란은 「홈 파티」에서 다음과 같이 질문한다. “한 사람이 다른 사람의 자리에 서보는 건 얼마나 어려운 일인가?”(24쪽) 타인의 공간을 방문하는 일은 다른 사람을 이해하는 확장의 길이 될까, 아니면 서로의 기준을 꺾어 누르는 침입의 길이 될까. 어느 때보다 ‘나’라는 테두리를 벗어나 ‘우리’로 나아가기 어려운 현실 속에서, 눈앞의 풍경과 나와 관계 맺는 사람이 돈으로 치환 가능한 숫자가 되어가는 현실 속에서 김애란의 질문은 더욱 절실하게 다가온다. 그리고 그 질문은 이렇게 바꿔 물을 수 있다. 공통의 포기와 낙담을 경험하고 다시금 새로운 출발선이 펼쳐졌을 때, 과연 그전과 무엇이 달라졌고 무엇이 지켜졌느냐고. 또는 무엇이 달라지고 무엇이 지켜져야만 하느냐고. 그것은 바로 누군가에게 안녕과 평안을 묻는 일이 더없이 간절해진 지금 우리에게 필요한 김애란식의 인사일 것이다. | E24: 김애란 | F24: 문학동네 | G24: 2025-06-20 | H24: 16800 | I24: 15120 | J24: 10 | K24: 0 | L24: 1064 | M24: 9.7 | N24: 소설 | O24: https://contents.kyobobook.co.kr/sih/fit-in/200x0/pdt/9791141602376.jpg
A25: S000218278239 | B25: 24 | C25: 니체의 초월자 | D25: 〈니체의 초월자〉는 유튜브 철학하루를 운영하고 있는 김철 작가의 두 번째 인문 책이다. 니체 철학의 주요 사상은 초월자가 되는 것이다. 초월자라는 것은 신이 되거나 남보다 특별한 존재가 되라는 뜻이 아니다. 내가 옳다고 믿는 길을 스스로 선택하는 삶을 뜻한다. 자신에게 주어진 고통을 초월하고 운명을 사랑하며 자신의 나태함, 게으름, 인간의 본성과 투쟁하여 끊임없이 더 나은 존재로 발전하는 사람을 뜻한다. 모두가 똑같은 방향을 바라보는 세상에서 다르게 생각한다는 건 용기가 필요한 일이 되어버렸다. 외로움을 견디지 못해 방황하는 사람은 늘어나고 있으며 수없이 많은 고통 앞에서 좌절하는 사람 또한 시대가 편리해짐에 따라 오히려 더 늘어나고 있다. 그런 현대인에게 니체는 묻는다. 당신은 당신 자신이 되었는가? 다양한 인간관계를 맺고 살아가지만 결국 끝까지 함께해야 할 사람은 나 자신이다. 세상이 아무리 흔들려도 내가 중심이 잡혀 있으면 흔들리지 않는다. 세상이 아무리 외롭고 고독해져도 내가 내 안에서 충만하다면 흔들리지 않는다. 세상의 기준이 흔들리고 복잡할수록 세워야 하는 것은 나만의 기준이다. 이 책은 철학을 해석하지 않는다. 대신, 지금의 세상을 견디며 나답게 살아가기 위한 니체식 사고법을 보여준다. 니체의 수많은 저서 중 현대인에게 도움이 될만한 이야기를 엄선하여 77편을 편역하였다. 남이 정한 정답이 아닌 스스로의 기준으로 살아가는 인간, 그것이 이 시대의 초월자다. 넘어져도 다시 일어나라. 타인이 세워놓은 가치를 따르지 말고 내 안의 별을 따르라. 나에게 준 운명을 부정하지 마라. 삶은 사랑할 수 없는 것까지 사랑하는 것이다. | E25: 프리드리히 니체 | F25: 히읏 | G25: 2025-10-28 | H25: 16900 | I25: 15210 | J25: 10 | K25: 0 | L25: 271 | M25: 9.8 | N25: 인문 | O25: https://contents.kyobobook.co.kr/sih/fit-in/200x0/pdt/9791192559100.jpg
A26: S000220351981 | B26: 25 | C26: 말문이 막힐 때 꺼내 쓰는 대화의 기술 | D26: 결국 통하는 말은 따로 있다 수많은 기업이 먼저 찾는 커뮤니케이션 전문가, 그녀가 밝혀낸 관계를 움직이는 대화의 원칙 말을 잘하는 사람은 어떻게 사람들의 마음을 사로잡을까? 그 비결은 단순히 유창함이나 논리적인 설명 능력에 있는 걸까? 이 책의 저자는 오랜 현장 경험을 통해 뛰어난 소통의 핵심은 화려한 화술이 아니라 상대를 이해하고 공감하는 태도에 있다고 말한다. 저자는 교육심리학을 바탕으로 기업 커뮤니케이션 교육과 조직 컨설팅을 수행해 온 전문 트레이너다. 바이두, 레노버를 비롯한 300개 이상의 기업에서 1만 명이 넘는 직장인을 대상으로 소통 교육을 진행했으며, 실제 업무 현장에서 검증된 다양한 커뮤니케이션 기법을 체계적으로 정리해 왔다. 특히 바이두의 고객 응대 및 영업 조직 교육에 참여하며 구축한 소통 훈련 체계는 높은 평가를 받았고, 이후 여러 기업으로 확산되어 적용되었다. 이 책에는 상대와 빠르게 신뢰를 쌓는 방법, 성향에 따라 다르게 접근하는 대화 전략, 오해를 줄이면서 정확하게 전달하는 표현법, 감정을 조절하며 소통하는 방법 등 실생활에 바로 활용할 수 있는 다양한 노하우가 담겨 있다. 또한 실제 사례와 상황별 예시를 통해 누구나 쉽게 이해할 수 있도록 구성했으며, 단원마다 스스로 연습해 볼 수 있는 실전 훈련법도 수록했다. 통하는 말은 단순히 관계를 부드럽게 만드는 데 그치지 않는다. 때로는 새로운 기회를 만들고, 예상치 못한 인연을 연결하며, 인생의 방향까지 바꾸기도 한다. 인간관계가 어렵게 느껴지는 사람, 직장과 일상에서 소통의 벽을 자주 경험하는 사람이라면 이 책을 통해 대화의 본질을 새롭게 발견하게 될 것이다. | E26: 장신웨 | F26: 알토북스 | G26: 2026-07-20 | H26: 17800 | I26: 16020 | J26: 10 | K26: 0 | L26: 1 | M26: 10 | N26: 자기계발 | O26: https://contents.kyobobook.co.kr/sih/fit-in/200x0/pdt/9791194655381.jpg
A27: S000220119843 | B27: 26 | C27: 부의 갈림길 | D27: ★★★ 60만 독자가 열광한 『부의 대이동』, 『환율의 대전환』 작가의 최신작 ★★★ tvN 〈유퀴즈〉, KBS 〈세계는 지금〉, 유튜브 〈지식인사이드〉 화제의 인물 지정학적 분쟁, K자 경제, 신임 연준 의장 케빈 워시, AI 혁명, 달러 패권의 향방 등 세계 경제의 판도를 뒤흔들 다섯 가지 거대 갈림길이 온다. 기존의 공식이 통하지 않고. 갈수록 높아지는 변동성으로 길이 보이지 않을 때 거시경제 전문가 오건영이 제시하는 부의 이정표를 살펴보자. 포트폴리오를 재편하고, 부가 지나는 길목을 선점할 수 있을 것이다. | E27: 오건영 | F27: 포레스트북스 | G27: 2026-06-10 | H27: 27000 | I27: 24300 | J27: 10 | K27: 0 | L27: 120 | M27: 9.83 | N27: 경제/경영 | O27: https://contents.kyobobook.co.kr/sih/fit-in/200x0/pdt/9791124591048.jpg
A28: S000219732915 | B28: 27 | C28: 품격 있는 대화를 위한 지식 브리핑 | D28: 매일 아침 100만 명의 뉴스를 책임지는 앵커 김진의 첫 책. 16년간 취재 기자이자 간판 뉴스 앵커로 활동해온 저자는 역설적으로 "뉴스는 세상의 진짜 지식을 말해주지 않는다"고 단언한다. 120만 구독자를 보유한 유튜브 채널 〈꽉TV〉와 시사 프로그램 〈김진의 돌직구쇼〉를 통해 복잡한 현안을 명쾌하게 풀어온 그가, 이번에는 뉴스 이면에 숨겨진 세상의 설계도를 한 권의 책에 담아냈다. 이 책은 정치, 경제, 사회, 문화, 국제 등 5개 분야를 관통하는 핵심 주제를 다룬다. ‘죄수의 딜레마’부터 ‘깨진 유리창 이론’, ‘투키디데스의 함정’, ‘민스키 모멘트’에 이르기까지 방대한 인문·사회과학적 개념을 실제 뉴스 사건에 정교하게 대입했다. 파편화된 정보와 알고리즘의 홍수 속에서 현상의 본질을 꿰뚫기 위해서는 구조를 읽어내는 눈이 필수적이다. 저자가 정리한 50가지 지적 프레임은 복잡한 세상 속에서 흔들리지 않는 '나만의 사고 기준'을 세워주는 단단한 기초가 되어줄 것이다. 어느 페이지를 먼저 읽어도 좋다. 흩어져 있던 뉴스들이 하나의 맥락으로 연결되는 순간, 세상을 보는 지도는 선명해진다. 품격 있는 대화는 유려한 말기술이 아니라 사안을 바라보는 '이해의 깊이'에서 완성된다. 이 책은 당신의 대화에 깊이를, 사고에 무게를 더해줄 것이다. | E28: 김진 | F28: 북플레저 | G28: 2026-05-06 | H28: 25000 | I28: 22500 | J28: 10 | K28: 0 | L28: 236 | M28: 9.67 | N28: 인문 | O28: https://contents.kyobobook.co.kr/sih/fit-in/200x0/pdt/9791124038413.jpg
A29: S000219545519 | B29: 28 | C29: 다크 심리학 2 | D29: “세상은 선(善)하다고 해서 절대 지켜주지 않는다.” 한층 더 심화한 《다크 심리학 2》를 통해 권력 뒤에 숨겨진 세상의 진실을 깨달아라! 우리가 흔히 말하는 ‘권력’은 대통령과 정치인, 대기업 회장처럼 높은 지위에 있는 사람이나 검찰, 경찰, 군대처럼 강력한 권한을 가진 집단이다. 또 권력을 떠올리면 ‘아부, 청탁, 뒷돈’ 같은 부정적 이미지를 연상하면서 ‘나와 상관없는 일’이라 여긴다. 어쩌면 당연하다. 권력을 논할 여유조차 없이 치열한 생존경쟁이 우리의 일상이기 때문이다. 그런데 제아무리 노력해도 원하는 결과가 보장되지 않는다. ‘도대체 왜, 무엇이 문제일까?’ 《다크 심리학 2》는 이 질문에서 비롯된다. ‘권력’은 엘리트층이나 특정 집단에만 있는 것이 아니다. 학교, 직장, 가정 등 우리가 속한 모든 관계를 통해 사회 전체를 관통하는 ‘네트워크’ 역시 권력이다. 문제는, 이 네트워크 시스템이 다크 트라이어드(Dark Triad)에게 유리하도록 설계되어 있다는 것이다. 그러므로 권력에 대한 이해는 현대 사회에 꼭 필요한 생존법이다. 지금 우리의 삶이 힘들고, 원하는 결과가 멀게 느껴지는 건 결코 우연이 아니다. 왜냐, 세상의 모든 것은 설계된 시스템과 같으며, 그 시스템에는 ‘강자의 의도’가 담겨 있기 때문이다. 권력은 우리에게 직접 명령하지 않는다. 우리 스스로가 통제하는 시스템을 만든다. 그런데 진짜 무서운 건 시스템이 아니다. 바로 ‘조종당하는’ 사실조차 모르는 자기 자신이다. 전편 《다크 심리학》이 관계 속 ‘심리 조종’을 다뤘다면, 《다크 심리학 2》는 심리학과 철학, 역사, 문화 등에 기반해 ‘인간 본성과 권력’, 그리고 ‘권력 구조(시스템) 내 다크 트라이어드’의 심리 전략을 심도 있게 다룬다. 각 챕터에 구성한 〈권력의 설계와 작동 원리〉, 〈다크 심리학과 권력 시스템〉, 〈악의 구조와 범죄 심리〉 등으로 ‘힘의 메커니즘’을 깨닫고, 다크 트라이어드 성향자의 다양한 사례를 통해 그들의 심리적 조작과 물리적 피해에서 벗어날 수 있다. “강자는 본능으로 움직이고, 약자는 학습으로 버틴다. 그러나 ‘깨달은 약자’는 더 이상 먹잇감이 아니다. 당신은 어느 쪽인가? 선택은 당신의 몫이다.” | E29: 다크 사이드 프로젝트 | F29: 어센딩 | G29: 2026-04-24 | H29: 24200 | I29: 21780 | J29: 10 | K29: 0 | L29: 250 | M29: 9.89 | N29: 인문 | O29: https://contents.kyobobook.co.kr/sih/fit-in/200x0/pdt/9791198754097.jpg
A30: S000000479333 | B30: 29 | C30: 프로젝트 헤일메리 | D30: 전 세계 SF 팬들을 사로잡은 화제의 소설 《프로젝트 헤일메리》가 마침내 스크린으로 향한다. 한국에서도 초판 출간 이후 꾸준히 사랑받으며 “과학과 우주를 사랑하는 사람들에게 짜릿한” 순간을 선사해온 이 소설의 영화 판권은 치열한 경쟁 끝에 아마존 MGM이 따낸 지 5년 만에 막바지 작업만을 남겨두고 있다. 예고편 공개만으로 7억 회가 넘는 조회 수가 입증하듯, 영화 애호가뿐만 아니라 이 책의 영상화를 간절히 바라온 독자들도 한껏 기대감을 안고 개봉일을 기다리고 있다. 앤디 위어는 데뷔작 《마션》과 후속작 《아르테미스》 그리고 이 책까지 단 세 권을 발표해 잇달아 성공을 거두며 뉴욕 타임스와 아마존 베스트셀러에 이름을 올린 명실상부 최고의 SF 작가이다. 글을 쓸 때 과학적 사실을 조사하고 검증하는 것으로 정평이 난 작가의 작품인 만큼, 흠잡을 데 없는 과학적 지식이 작가의 장기인 낙관적 감수성과 어우러져 유감없이 그려졌다. 특히 작가가 치밀하게 구상한 ‘특별한 캐릭터’의 등장은 단연 소설의 백미다. 지구를 구하기 위해 우주로 떠난 한 사람 그리고 그 여정에서 만나는 ‘절대 잊히지 않는 존재’. 이 소설은 과학소설의 외피를 쓴 채 공생과 연대, 종을 넘어서는 우정에 관해 “콸콸 솟는 이야기 샘물”을 퍼 나른다. 인류를 살리기 위해 자신의 귀환을 포기한 ‘좋은 사람’의 선택은 어떤 결말을 맞을 것인가. 한층 깊어지고 넓어진 앤디 위어의 세계 속에 그 답이 있다. 이 이야기는 분명, 책으로도 영화로도 오래 기억될 것이다. | E30: 앤디 위어 | F30: 알에이치코리아 | G30: 2026-02-19 | H30: 22000 | I30: 19800 | J30: 10 | K30: 0 | L30: 1537 | M30: 9.88 | N30: 소설 | O30: https://contents.kyobobook.co.kr/sih/fit-in/200x0/pdt/9788925588735.jpg
A31: S000218674965 | B31: 30 | C31: 2026 큰별쌤 최태성의 별별한국사 한국사능력검정시험 심화(1,2,3급)(상) | D31: "〈2026 큰별쌤 최태성의 별별한국사 한국사능력검정시험 심화 상〉 오랜 연구와 검증으로 한국사에 기초가 전혀 없는 사람도 단기간에 한능검에 합격할 수 있는 최적의 구성을 완성하였습니다. 판서의 장인 큰별쌤 최태성이 핵심만을 모아 만든 아트 판서를 수록하고, 시험에 자주 등장하는 사료, 사진, 지도 등을 모아 해설하여 합격을 위한 필수 개념을 익히기 쉽게 하였습니다. 또한, 한능검 기출문제를 모두 분석한 후, 기출 선택지를 이용한 별 채우기 문제를 수록하여 자연스럽게 기출 선택지가 기억될 수 있도록 하였고, 반복적으로 출제되는 주제의 최신 기출문제를 꼼꼼하고 친절한 해설과 함께 담아 실전에 대비할 수 있도록 하였습니다. 여기에 한국사 연표와 지역의 역사를 담은 지도를 통해 한국사 흐름잡기가 더욱 쉬울 것입니다. 제시된 이미지는 책의 뒷표지입니다. 〈2026 큰별쌤 최태성의 별별한국사 한국사능력검정시험 심화(1·2·3급) 상〉의 앞표지는 1억원 기부를 통해 사랑의 열매 '아너 소사이어티'에 가입되도록 함께 지원해 주신 최태성 1, 2TV 별님들로 구성되었습니다." | E31: 최태성 | F31: 이투스북 | G31: 2025-12-09 | H31: 19000 | I31: 17100 | J31: 10 | K31: 0 | L31: 394 | M31: 9.9 | N31: 인문 | O31: https://contents.kyobobook.co.kr/sih/fit-in/200x0/pdt/9791138934428.jpg
... A35: S000001632467 | B35: 34 | C35: 모순 | D35: 양귀자 소설의 힘을 보여준 베스트셀러 『모순』. 1998년에 초판이 출간된 이후 132쇄를 찍으며 여전히 많은 사랑을 받고 있는 작품을, 오래도록 소장할 수 있는 양장본으로 새롭게 선보인다. 스물다섯 살 미혼여성 안진진을 통해 모순으로 가득한 우리의 인생을 들여다본다. 작가 특유의 섬세한 문장들로 여러 인물들의 삶을 생생하게 그려내고 있다. 시장에서 내복을 팔고 있는 억척스런 어머니와 행방불명 상태로 떠돌다 가끔씩 귀가하는 아버지, 조폭의 보스가 인생의 꿈인 남동생을 가족으로 둔 안진진. 어머니와 일란성 쌍둥이인 이모는 부유하지만 지루한 삶에 지쳐 있고, 가난한 어머니는 처리해야 할 불행들이 많아 지루할 틈이 없다. 안진진은 사뭇 다른 어머니와 이모의 삶을 바라보며 모순투성이인 삶을 어떻게 이해해야 하는지 고민하기 시작하는데…. | E35: 양귀자 | F35: 쓰다 | G35: 2013-04-01 | H35: 13000 | I35: 11700 | J35: 10 | K35: 0 | L35: 3833 | M35: 9.79 | N35: 소설 | O35: https://contents.kyobobook.co.kr/sih/fit-in/200x0/pdt/9788998441012.jpg
A36: S000220573907 | B36: 35 | C36: 황천의 츠가이 11 | E36: Hiromu Arakawa | F36: 대원씨아이 | G36: 2026-07-31 | H36: 6500 | I36: 5850 | J36: 10 | K36: 0 | L36: 0 | M36: 0 | N36: 만화 | O36: https://contents.kyobobook.co.kr/sih/fit-in/200x0/pdt/9791142358777.jpg
A37: S000218791163 | B37: 36 | C37: ETS 토익 정기시험 기출문제집 1000 Vol 5 RC | D37: 1. 최신 기출문제 전격 공개! 이 책에는 토익 정기시험 최신 기출문제 10회가 수록되어 있다. 시험에 나온 최신 기출문제로 실전 감각을 키워 시험에 확실하게 대비하자! 2. 고난도 문항 무료 동영상 강의! 교재 내 QR코드는 해당 회차의 무료 동영상 강의로 연결된다. 오답률 높은 고난도 문항을 친절한 해설 강의와 함께 완벽 마스터하자! 3. 기출 포인트를 꿰뚫는 명쾌한 해설! 최신 출제경향을 가장 정확하게 알 수 있는 기출문제를 풀고 출제 포인트가 보이는 명쾌한 해설로 토익을 정복해 보자! 4. ETS 토익 온라인/모바일 학습 지원! 온라인 학습 커뮤니티(www.etstoeicbook.co.kr)를 통해 교재 소개 및 학습 콘텐츠, 정기시험 대비특강을 지원한다. 또한 동영상 강의, 기출어휘 단어장, 기출테스트 채점/분석 등을 지원하는 토익 필수템 'ETS 토익기출 수험서 앱'으로 보다 스마트하게 학습해 보자! | E37: ETS | F37: YBM | G37: 2025-12-15 | H37: 22000 | I37: 19800 | J37: 10 | K37: 0 | L37: 275 | M37: 9.86 | N37: 외국어 | O37: https://contents.kyobobook.co.kr/sih/fit-in/200x0/pdt/9788917243802.jpg
A38: S000061351196 | B38: 37 | C38: 유럽 도시 기행 2 | D38: "이 책은 힘들게 마음먹은 유럽 도시를 알차고 풍성하게 여행하거나 미디어를 통해 어렴풋이 알고 있는 유럽의 도시를 제대로 알고 싶을 때, 누군가 콕콕 찍어서 알려 줬으면 하는 내용이 빼곡히 들어있다. 도시의 매력을 느낄 수 있는 핫플레이스부터, 각 도시의 건축물, 길과 광장, 박물관과 예술품 등 그 무엇을 만나도 당황하지 않을 탄탄한 배경 지식, 도시의 존재감을 만들어낸 세계사적 사건과 인물들, 유럽의 역사와 도시의 역사가 씨줄과 날줄처럼 교차하며 생긴 도시의 서사와 상흔들까지, 우리가 도시를 더 풍성하게 만끽할 수 있는 흥미진진한 이야기를 펼친다. 여기에 도시와 인간, 그리고 삶을 바라보는 작가의 지적 통찰력이 더해져 도시가 품은 가치와 맥락, 의미 있는 서사들이 우리의 현재와 어떻게 교감하는지를 보여준다." 사람이 만든 것에는 이야기가 있다. 인간이 만든 가장 크고 아름답고 오래된 것은 아마 도시일 것이다. 도시는 역사적 사건과 인물들이 만든 생생하고, 드라마틱한 낯선 이야기가 깃들어 있다. 특히 유럽의 도시는 박물관이나 왕궁에서뿐 아니라 광장, 건물, 카페, 골목 등과 같은 일상의 공간들도 흥미로운 히스토리를 품고 있는 곳이 많다. 작가는 이러한 유럽의 도시 공간이 전하는 이야기들을 들을 수 있게, 도시의 표면 아래 숨겨진 이야기를 찾고 도시가 품고 있는 인물들의 삶을 돌아보며 오늘의 도시가 탄생하기까지 영광과 상처, 야만과 관용, 성과 속, 단절과 연결, 좌절과 성취, 삶과 죽음 등을 그만의 시선으로 마주한다. 작가가 전하는 도시 공간과 그 속에 담긴 이야기는 인간이 앞으로 나아온 성취의 과정과 그 과정에서 표출한 아름다움과 추함, 이기심과 이타심, 절망과 희망 같은 인간의 다양한 얼굴을 보여주며 현재를 비춘다. 이것은 우리 자신을 더 입체적으로 느끼게 하고 평소와는 다른 낯선 생각과 감정을 불러일으키며 자신과 마주하게 한다. 아마도 이것이 멀지만 낯선 거리를 걷고 또 걸으며 유럽의 도시를 여행하는 이유가 아닐까. | E38: 유시민 | F38: 생각의길 | G38: 2022-07-09 | H38: 17500 | I38: 15750 | J38: 10 | K38: 0 | L38: 243 | M38: 9.72 | N38: 인문 | O38: https://contents.kyobobook.co.kr/sih/fit-in/200x0/pdt/9788965137702.jpg
A39: S000220567031 | B39: 38 | C39: 에스콰이어(ESQUIRE)(2026년 8월호) | D39: 『에스콰이어(ESQUIRE)』는 취향있는 남자들을 위한 지적인 바이블 매거진이다. | E39: 허스트중앙 편집부 | F39: 허스트중앙 | G39: 2026-07-23 | H39: 8000 | I39: 7600 | J39: 5 | K39: 0 | L39: 0 | M39: 0 | N39: 잡지 | O39: https://contents.kyobobook.co.kr/sih/fit-in/200x0/pdt/3904000621647.jpg
A40: S000214700980 | B40: 39 | C40: 완자 고등 통합과학 2(2026) | D40: [교재 소개] 1. 혼자서도 교과 개념을 익히고 내신 시험을 준비할 수 있는 ‘완벽한 자율 학습서’ 입니다. 2. 고등 통합과학의 핵심 개념을 쉽고 체계적으로 정리한 교재입니다. 3. 2022개정 교육과정에 해당하는 전국의 기출문제를 분석하여 기출 경향에 맞게 개선한 교재입니다. | E40: 김은경 외 | F40: 비상 | G40: 2024-11-01 | H40: 18500 | I40: 16650 | J40: 10 | K40: 0 | L40: 500 | M40: 9.8 | N40: 중/고등참고서 | O40: https://contents.kyobobook.co.kr/sih/fit-in/200x0/pdt/9791173161896.jpg
A41: S000220447668 | B41: 40 | C41: 읽는 기도: 휴거 깨어있으라 | D41: 『휴거 깨어 있으라』의 출간 목적은 독자를 불안하게 만들거나 공포를 조장하는 데 있지 않다. 오히려 아직 기회가 있을 때 하나님께 돌아가고, 삶의 자리에서 죄에 무뎌지지 않으며, 말씀과 기도로 주님을 기다리는 믿음을 회복하도록 권면하는 데 있다. 이 책은 휴거를 단순한 종말의 공포나 미래에 대한 추측으로 다루지 않는다. 오히려 “항상 기도하며 깨어 있으라”는 말씀처럼, 매일의 말과 생각, 관계와 선택 속에서 하나님을 의식하며 살아가는 것이 무엇인지 구체적으로 돌아보게 한다. 숨겨진 죄와 반복되는 습관, 감정과 언어, 말씀과 기도, 예배와 공동체 생활까지 점검하는 ‘휴거 대비 영적 점검 리스트 100개’는 독자가 자신의 믿음을 정죄가 아닌 회복의 자리에서 살펴보도록 한다. 저자는 휴거 이후의 7년 대환난, 적그리스도와 짐승의 표, 아마겟돈 전쟁, 천년왕국, 새 하늘과 새 땅에 이르는 흐름도 함께 다룬다. 해석의 차이와 논의가 이어져 온 요한계시록의 본문들을 단순한 자극이나 억측으로 풀어내기보다, 성경의 여러 말씀을 연결하여 독자가 말씀 안에서 직접 생각하고 분별할 수 있도록 안내한다. 마지막에는 마음과 영혼, 말씀과 기도, 삶의 방향, 예배와 공동체를 차례로 돌아보는 4주간의 준비 과정을 담았다. 막연히 재림을 기다리는 데 그치지 않고, 오늘 하루를 어떻게 살아야 하는지 실제적으로 붙들어 주는 구성이다. 재림과 휴거에 관한 성경적 흐름을 이해하고 싶은 독자, 자신의 믿음과 삶을 다시 점검하고 싶은 성도, 말씀 안에서 깨어 있는 삶을 회복하고 싶은 이들에게 이 책은 조용하지만 분명한 영적 안내서가 되어 줄 것이다. | E41: 무명의 기도자 | F41: 더하트 | G41: 2026-07-14 | H41: 8800 | I41: 7920 | J41: 10 | K41: 0 | L41: 119 | M41: 9.9 | N41: 종교 | O41: https://contents.kyobobook.co.kr/sih/fit-in/200x0/pdt/9791194177616.jpg
A42: S000218942259 | B42: 41 | C42: 돈의 심리학(50만 부 기념 뉴 에디션) | D42: 출간과 동시에 전 세계 금융계에 큰 반향을 일으키며 “투자의 패러다임을 바꾼 책”이라는 찬사를 받은 《돈의 심리학》이 국내 누적 판매 50만 부를 돌파하며 뉴 에디션으로 돌아왔다. 이번 50만 부 기념 에디션에는 저자 모건 하우절이 새롭게 집필한 ‘두 번째 보너스 스토리’가 수록되었다. 저자는 2021년 출간 이후 급변하는 시장을 지속적으로 관찰하며 한 가지 사실을 더욱 분명하게 확신하게 되었다. 부의 원칙은 변하지 않지만, 사람들은 늘 같은 실수를 반복한다는 것. 시장은 끊임없이 요동치지만, 공포와 탐욕, 비교와 후회 같은 인간의 심리는 놀라울 만큼 비슷한 방식으로 되풀이된다. 이번에 추가된 보너스 스토리는 이처럼 변하지 않는 부의 본질을 다시 한번 정확히 짚어내며, 독자들에게 흔들리지 않는 투자 철학을 전한다. 인간의 심리에서 비롯된 선택들이 어떻게 장기적인 자산 격차로 이어지는지 명쾌하고 설득력 있게 풀어낸 《돈의 심리학》은 월가의 전설 하워드 막스, 《아주 작은 습관의 힘》의 저자 제임스 클리어 등 세계적 거장들과 국내외 주요 언론의 극찬을 받으며 이제 단순한 베스트셀러를 넘어 투자의 ‘교과서’이자 시대를 관통하는 고전으로 자리매김했다. 모건 하우절이 제시하는 ‘돈의 심리학’은 독자들의 투자 여정을 지켜주는 단단한 이정표가 되어줄 것이다. | E42: 모건 하우절 | F42: 인플루엔셜 | G42: 2026-01-14 | H42: 24800 | I42: 22320 | J42: 10 | K42: 0 | L42: 222 | M42: 9.88 | N42: 경제/경영 | O42: https://contents.kyobobook.co.kr/sih/fit-in/200x0/pdt/9791168343443.jpg
A43: S000218674985 | B43: 42 | C43: 2026 큰별쌤 최태성의 별별한국사 한국사능력검정시험 심화(1,2,3급)(하) | D43: "〈2026 큰별쌤 최태성의 별별한국사 한국사능력검정시험 심화 하〉 오랜 연구와 검증으로 한국사에 기초가 전혀 없는 사람도 단기간에 한능검에 합격할 수 있는 최적의 구성을 완성하였습니다. 판서의 장인 큰별쌤 최태성이 핵심만을 모아 만든 아트 판서를 수록하고, 시험에 자주 등장하는 사료, 사진, 지도 등을 모아 해설하여 합격을 위한 필수 개념을 익히기 쉽게 하였습니다. 또한, 한능검 기출문제를 모두 분석한 후, 기출 선택지를 이용한 별 채우기 문제를 수록하여 자연스럽게 기출 선택지가 기억될 수 있도록 하였고, 반복적으로 출제되는 주제의 최신 기출문제를 꼼꼼하고 친절한 해설과 함께 담아 실전에 대비할 수 있도록 하였습니다. 여기에 한국사 연표와 지역의 역사를 담은 지도를 통해 한국사 흐름잡기가 더욱 쉬울 것입니다. 제시된 이미지는 책의 뒷표지입니다. 〈2026 큰별쌤 최태성의 별별한국사 한국사능력검정시험 심화(1·2·3급) 하〉의 앞표지는 1억원 기부를 통해 사랑의 열매 '아너 소사이어티'에 가입되도록 함께 지원해 주신 최태성 1, 2TV 별님들로 구성되었습니다." | E43: 최태성 | F43: 이투스북 | G43: 2025-12-09 | H43: 18500 | I43: 16650 | J43: 10 | K43: 0 | L43: 311 | M43: 9.92 | N43: 인문 | O43: https://contents.kyobobook.co.kr/sih/fit-in/200x0/pdt/9791138934442.jpg
A44: S000220241328 | B44: 43 | C44: 지적인 삶을 위한 열 가지 철학 | D44: “왜 우리는 같은 말을 하면서도 끝없이 싸우는가?” 정의, 자유, 권력, 노동, 전쟁… 당연하다고 믿었던 단어들의 정체를 파헤치는 가장 지적인 ‘세계 해석 수업’ 직장 회의실에서, 온라인 토론장에서, 심지어 가장 사적인 대화에서조차 우리는 문득 기묘한 단절감을 느낀다. 분명 같은 한국어로 대화하는데 논의는 평행선을 달리고, 격렬하게 부딪히면서도 정작 무엇 때문에 싸우는지 모호한 순간들. ‘말이 통하지 않는다’는 이 고질적인 감각의 원인은 무엇일까. 일본의 대표적인 대중 철학자 오카모토 유이치로 교수는 그 원인을 이렇게 진단한다. 우리는 똑같은 단어를 내뱉으면서도 머릿속으로는 전혀 다른 세계를 그리고 있다고. 대화가 깊어질수록 오해의 골만 깊어지는 ‘불통’의 시대인 이유다. 이 불통의 안개를 걷어 내기 위해 저자가 꺼내 든 도구는 다름 아닌 ‘철학’이다. 철학은 흔히 현실과 동떨어진 현학적 말장난으로 치부되지만, 사실 우리 사회를 움직이는 언어와 개념의 의미를 분석하는 가장 강력한 도구다. 마르크스 가브리엘이 “세계는 존재하지 않는다”고 선언할 때, 하이데거가 인간을 ‘세계 속의 존재’라고 규정할 때 여기서 중요한 것은 누가 옳고 그르냐가 아니다. 두 사람이 ‘세계’라는 단어 하나를 통해 각기 다른 맥락과 사유의 층위를 조명하고 있다는 사실, 바로 그것이다. 철학자들의 치열한 사유를 빌려 단어의 다층적 의미를 이해하는 과정은 사고의 혼란을 잠재우고 논리의 뼈대를 바로 세우는 강력한 무기가 된다. 이 책은 우리가 완전히 안다고 착각하는 열 가지 핵심 개념-정의·기술·권력·폭력·자유·노동·소외·국가·종교·전쟁-이 시대와 철학자에 따라 어떻게 변주되어 왔는지를 치밀하게 파고든다. 일상에서 숨 쉬듯 쓰는 단어이지만, 그 이면에는 인류 지성사가 부딪히며 쌓아 온 거대한 논쟁의 역사가 잠들어 있다. 존 롤스의 ‘공정함’과 아리스토텔레스의 ‘미덕’이 충돌하는 지점, 이사야 벌린이 말한 ‘소극적 자유’와 ‘적극적 자유’가 오늘날 우리의 선택을 어떻게 규정하는지를 짚어 내며 상식을 근본적으로 뒤흔든다. 당연했던 단어들이 가면을 벗고 낯선 얼굴을 드러내는 순간, 독자의 사고 지평은 비로소 넓어진다. 저자의 통찰은 과거의 박제된 철학에 머물지 않는다. 디지털 감시 체제와 미셸 푸코의 권력론을 연결하고, AI와 로봇 시대의 노동을 한나 아렌트의 시선으로 재해석하는 대목은 이 책이 왜 ‘지금, 여기를 살아가는 우리’를 위한 가장 실용적인 지침서인지를 증명한다. 방대한 철학사를 관통하면서도 무게에 눌리지 않는 저자 특유의 명쾌한 구조화 능력은 복잡한 세상을 단숨에 읽어 내고자 하는 현대인들에게 짜릿한 지적 쾌감을 선사할 것이다. 단어 하나를 제대로 정의한다는 것은 단순한 지식 습득을 넘어 세상을 보는 눈을 새롭게 벼리는 일이다. 이 책의 마지막 장을 덮고 나면, 이전과 똑같은 단어를 사용하면서도 전혀 다른 차원의 세계를 목격하게 된다. 상대방의 논리 너머에 숨겨진 진짜 의도를 꿰뚫어 보고, 모호한 감정이 아닌 명료한 언어로 자신만의 세계를 구축하고 싶은 이들에게 이 책은 가장 확실한 지도가 되어 줄 것이다. | E44: 오카모토 유이치로 | F44: 이든서재 | G44: 2026-07-10 | H44: 19800 | I44: 17820 | J44: 10 | K44: 0 | L44: 9 | M44: 10 | N44: 인문 | O44: https://contents.kyobobook.co.kr/sih/fit-in/200x0/pdt/9791194812234.jpg
A45: S000218791156 | B45: 44 | C45: ETS 토익 정기시험 기출문제집 1000 Vol 5 LC | D45: 1. 최신 기출문제 전격 공개! 이 책에는 토익 정기시험 최신 기출문제 10회가 수록되어 있다. 시험에 나온 최신 기출문제로 실전 감각을 키워 시험에 확실하게 대비하자! 2. 실제 정기시험 성우 음성으로 실전 대비! 이 책에 수록된 10회의 LC 음원은 모두 정기시험 성우의 음원이다. 시험장에서 듣게 될 음성으로 공부하면 까다로운 영국식, 호주식 발음도 걱정 없다. 또한 강도 높은 학습을 위해 고속 버전과 소음 버전을 추가로 제공하며, YBM북스닷컴 출판 홈페이지 www.ybmbooks.com에서 무료로 다운로드 가능하다. 3 고난도 문항 무료 동영상 강의! 교재 내 QR코드는 해당 회차의 무료 동영상 강의로 연결된다. 오답률 높은 고난도 문항을 친절한 해설 강의와 함께 완벽 마스터하자! 4. 정확한 스크립트와 기출 포인트를 꿰뚫는 명쾌한 해설! 최신 출제경향을 가장 정확하게 알 수 있는 기출문제를 풀고 정확한 스크립트와 출제 포인트가 보이는 명쾌한 해설로 토익을 정복해 보자! 5. ETS 토익 온라인/모바일 학습 지원! 온라인 학습 커뮤니티(www.etstoeicbook.co.kr)를 통해 교재 소개 및 학습 콘텐츠, 정기시험 대비특강을 지원한다. 또한 MP3 및 동영상 강의, 기출어휘 단어장, 기출테스트 채점/분석 등을 지원하는 토익 필수템 'ETS 토익기출 수험서 앱'으로 보다 스마트하게 학습해 보자! | E45: ETS | F45: YBM | G45: 2025-12-15 | H45: 22000 | I45: 19800 | J45: 10 | K45: 0 | L45: 241 | M45: 9.83 | N45: 외국어 | O45: https://contents.kyobobook.co.kr/sih/fit-in/200x0/pdt/9788917243796.jpg
A46: S000219024597 | B46: 45 | C46: 읽는기도: 회개스캔 | D46: 『회개 스캔』은 회개하고 싶지만 고백의 말이 떠오르지 않아 끝내 침묵해 버린 이들을 위한 11일 기도책입니다. 회개는 ‘말을 잘하는 기술’이 아니라, 하나님 앞에서 죄를 숨기지 않고 돌이키는 마음의 결단입니다. 이 책은 성경 말씀으로 시작해, 막혀 있던 회개의 첫 문장을 열어 줍니다. 『회개 스캔』은 4단계 회개 여정으로 구성됩니다. 죄를 깨닫는 회개(Day1), 죄를 통회하는 회개(Day2), 죄에서 돌이키는 회개(Day3-10), 그리고 최고의 영광을 맞이하는 회개(Day11)까지. 하루 한 장씩 따라가며 회개의 길을 구체적으로 걸어가도록 안내합니다. 매일의 흐름은 말씀-묵상-회개기도문-대적기도와 선포-마음의 결단-실천 미션으로 이어집니다. 기도하다 멈춰 서던 사람도 자연스럽게 회개의 흐름 안으로 들어가, 조용히 읽고 묵상하며 소리 내어 기도하는 자리에서 결단과 실천으로 나아가게 됩니다. 11일의 여정을 따라 걷다 보면, 닫혀 있던 기도의 문이 다시 열릴 것입니다. | E46: 무명의 기도자 | F46: 더하트 | G46: 2026-01-20 | H46: 8800 | I46: 7920 | J46: 10 | K46: 0 | L46: 281 | M46: 9.79 | N46: 종교 | O46: https://contents.kyobobook.co.kr/sih/fit-in/200x0/pdt/9791194177487.jpg
A47: S000218736039 | B47: 46 | C47: 2026 이지패스 ADsP 데이터분석 준전문가 | D47: <b>미어캣 2026 최신 기출문제 수록 앱 제공 | 비전공자 20일 완성</b> ◎ 빠르고 효율적인 공부를 위한 ADsP 수험서 방대한 데이터 분석 콘텐츠를 ADsP 출제 경향에 맞게 핵심적으로 간결하게 정리하여 시간에 쫓기는 수험생들에게 최대한 공부 효율을 높일 수 있도록 구성했습니다. ◎ 초심자, 비전공자들을 위해 이해하기 쉽게 풀어 쓴 ADsP 수험서 데이터 분석을 처음 접하는 초심자나 비전공자들이 이해하기 쉽도록 용어와 문장을 다듬었습니다. 아울러 초심자 비전공자를 위한 ‘EASY BOX’, 출제 경향과 중요도를 안내하는 ‘TIP-BOX’, 풍부한 설명을 담은 ‘참고-BOX’와 그래프, 표 등을 활용하여 이해하기 쉽도록 구성했습니다. ◎ 풍부한 R 실습 예제로 충분히 이해할 수 있도록 구성 R을 활용한 분석 실습 예제로 실제 적용 과정을 이해할 수 있어, 무작정 외우는 공부가 아닌 이해하는 공부가 될 수 있도록 구성했습니다. ◎ 총 1,904문항에 달하는 압도적인 문제편 각 절마다 등장하는 핵심문제, 기출유형문제, 예상문제, 모의고사 3회분, 기출변형문제 3회분 앱에 수록된 기출문제 등 총 1,904문항에 달하는 방대한 문제를 수록하여 문제를 통한 반복 훈련에 부족함이 없도록 구성했습니다. ◎ 유튜브 무료 강의(핵심 요약 벼락치기 특강) 제공 중요한 핵심 개념을 총정리 할 수 있는 ‘핵심 요약 강의’와 ‘기출문제 풀이’ 강의를 제공합니다. 교재와 함께 활용한다면 효율적인 학습을 할 수 있을 것입니다. ◎ 자투리 시간 활용을 위한 수험용 앱 제공 자투리 시간을 활용해 틈틈이 학습할 수 있는 수험용 앱을 제공합니다. 수험용 앱에서는 총 31회차의 모의고사 및 기출문제를 수록하고 있으며, 자동으로 채점해주는 기능과 오답노트 기능이 있어 효율적으로 학습할 수 있습니다. ◎ 독자의 궁금증을 해결해주는 Q&A 커뮤니티 운영 저자가 직접 답변해주는 Q&A 게시판과 온라인 스터디가 진행되는 커뮤니티를 운영합니다. 궁금한 점을 해결하고, 책에 수록되지 않은 정보와 최신 자료를 얻을 수 있습니다. ★ 이 책에서 다루는 내용 ★ ◎ 1과목 〈데이터 이해〉 - 데이터의 이해, 데이터의 가치와 미래, 가치 창조를 위한 데이터 사이언스와 전략 인사이트 ◎ 2과목 〈데이터 분석 기획〉 - 데이터 분석 기획의 이해, 분석 마스터플랜 ◎ 3과목 〈데이터 분석〉 - R 기초와 데이터 마트, 통계 분석, 정형 데이터 마이닝 | E47: 박현민 외 | F47: 위키북스 | G47: 2026-01-02 | H47: 30000 | I47: 27000 | J47: 10 | K47: 0 | L47: 327 | M47: 9.89 | N47: 컴퓨터/IT | O47: https://contents.kyobobook.co.kr/sih/fit-in/200x0/pdt/9791158396510.jpg
...
