Workbook

Sheet Dashboard
A1: YES24 베스트셀러 탐색적 데이터 분석(EDA) & KPI 대시보드
A4: 총 등록 도서 수 | B4: =COUNTA(RawData!C2:C878) | D4: 평균 판매지수 | E4: =AVERAGE(RawData!K2:K878) | G4: 평균 평점 | H4: =AVERAGE(RawData!M2:M878) | J4: 총 리뷰 건수 | K4: =SUM(RawData!L2:L878)
A7: TOP 10 출판사 요약 | G7: 도서 가격대별 분포
A8: 출판사명 | B8: 도서 건수 | C8: 평균 판매지수 | D8: 평균 평점 | E8: 총 리뷰건수 | G8: 가격구간 | H8: 도서 건수 | I8: 평균 판매지수
A9: =Analysis!A2 | B9: =Analysis!B2 | C9: =Analysis!C2 | D9: =Analysis!D2 | E9: =Analysis!E2 | G9: =Analysis!I2 | H9: =Analysis!J2 | I9: =Analysis!K2
A10: =Analysis!A3 | B10: =Analysis!B3 | C10: =Analysis!C3 | D10: =Analysis!D3 | E10: =Analysis!E3 | G10: =Analysis!I3 | H10: =Analysis!J3 | I10: =Analysis!K3
A11: =Analysis!A4 | B11: =Analysis!B4 | C11: =Analysis!C4 | D11: =Analysis!D4 | E11: =Analysis!E4 | G11: =Analysis!I4 | H11: =Analysis!J4 | I11: =Analysis!K4
A12: =Analysis!A5 | B12: =Analysis!B5 | C12: =Analysis!C5 | D12: =Analysis!D5 | E12: =Analysis!E5 | G12: =Analysis!I5 | H12: =Analysis!J5 | I12: =Analysis!K5
A13: =Analysis!A6 | B13: =Analysis!B6 | C13: =Analysis!C6 | D13: =Analysis!D6 | E13: =Analysis!E6 | G13: =Analysis!I6 | H13: =Analysis!J6 | I13: =Analysis!K6
A14: =Analysis!A7 | B14: =Analysis!B7 | C14: =Analysis!C7 | D14: =Analysis!D7 | E14: =Analysis!E7 | G14: =Analysis!I7 | H14: =Analysis!J7 | I14: =Analysis!K7
A15: =Analysis!A8 | B15: =Analysis!B8 | C15: =Analysis!C8 | D15: =Analysis!D8 | E15: =Analysis!E8
A16: =Analysis!A9 | B16: =Analysis!B9 | C16: =Analysis!C9 | D16: =Analysis!D9 | E16: =Analysis!E9 | G16: 도서 평점대별 분포
A17: =Analysis!A10 | B17: =Analysis!B10 | C17: =Analysis!C10 | D17: =Analysis!D10 | E17: =Analysis!E10 | G17: 평점구간 | H17: 도서 건수 | I17: 평균 판매지수
A18: =Analysis!A11 | B18: =Analysis!B11 | C18: =Analysis!C11 | D18: =Analysis!D11 | E18: =Analysis!E11 | G18: =Analysis!O2 | H18: =Analysis!P2 | I18: =Analysis!Q2
G19: =Analysis!O3 | H19: =Analysis!P3 | I19: =Analysis!Q3
G20: =Analysis!O4 | H20: =Analysis!P4 | I20: =Analysis!Q4
G21: =Analysis!O5 | H21: =Analysis!P5 | I21: =Analysis!Q5

Sheet Analysis
A1: 출판사 | B1: 도서건수 | C1: 평균판매지수 | D1: 평균평점 | E1: 총리뷰건수 | G1: 구간하한 | H1: 구간상한 | I1: 가격구간 | J1: 도서건수 | K1: 평균판매지수 | M1: 평점하한 | N1: 평점상한 | O1: 평점구간 | P1: 도서건수 | Q1: 평균판매지수
A2: 이레미디어 | B2: =COUNTIF(RawData!$F$2:$F$878, A2) | C2: =AVERAGEIF(RawData!$F$2:$F$878, A2, RawData!$K$2:$K$878) | D2: =AVERAGEIF(RawData!$F$2:$F$878, A2, RawData!$M$2:$M$878) | E2: =SUMIF(RawData!$F$2:$F$878, A2, RawData!$L$2:$L$878) | G2: 0 | H2: 10000 | I2: 1만원 이하 | J2: =COUNTIFS(RawData!$H$2:$H$878, ">="&G2, RawData!$H$2:$H$878, "<"&H2) | K2: =AVERAGEIFS(RawData!$K$2:$K$878, RawData!$H$2:$H$878, ">="&G2, RawData!$H$2:$H$878, "<"&H2) | M2: 0 | N2: 8 | O2: 8점 이하 | P2: =COUNTIFS(RawData!$M$2:$M$878, ">="&M2, RawData!$M$2:$M$878, "<"&N2) | Q2: =AVERAGEIFS(RawData!$K$2:$K$878, RawData!$M$2:$M$878, ">="&M2, RawData!$M$2:$M$878, "<"&N2)
A3: 길벗 | B3: =COUNTIF(RawData!$F$2:$F$878, A3) | C3: =AVERAGEIF(RawData!$F$2:$F$878, A3, RawData!$K$2:$K$878) | D3: =AVERAGEIF(RawData!$F$2:$F$878, A3, RawData!$M$2:$M$878) | E3: =SUMIF(RawData!$F$2:$F$878, A3, RawData!$L$2:$L$878) | G3: 10000 | H3: 15000 | I3: 1만~1.5만원 | J3: =COUNTIFS(RawData!$H$2:$H$878, ">="&G3, RawData!$H$2:$H$878, "<"&H3) | K3: =AVERAGEIFS(RawData!$K$2:$K$878, RawData!$H$2:$H$878, ">="&G3, RawData!$H$2:$H$878, "<"&H3) | M3: 8 | N3: 9 | O3: 8점초과~9점 | P3: =COUNTIFS(RawData!$M$2:$M$878, ">="&M3, RawData!$M$2:$M$878, "<"&N3) | Q3: =AVERAGEIFS(RawData!$K$2:$K$878, RawData!$M$2:$M$878, ">="&M3, RawData!$M$2:$M$878, "<"&N3)
A4: 김영사 | B4: =COUNTIF(RawData!$F$2:$F$878, A4) | C4: =AVERAGEIF(RawData!$F$2:$F$878, A4, RawData!$K$2:$K$878) | D4: =AVERAGEIF(RawData!$F$2:$F$878, A4, RawData!$M$2:$M$878) | E4: =SUMIF(RawData!$F$2:$F$878, A4, RawData!$L$2:$L$878) | G4: 15000 | H4: 20000 | I4: 1.5만~2만원 | J4: =COUNTIFS(RawData!$H$2:$H$878, ">="&G4, RawData!$H$2:$H$878, "<"&H4) | K4: =AVERAGEIFS(RawData!$K$2:$K$878, RawData!$H$2:$H$878, ">="&G4, RawData!$H$2:$H$878, "<"&H4) | M4: 9 | N4: 9.5 | O4: 9점초과~9.5점 | P4: =COUNTIFS(RawData!$M$2:$M$878, ">="&M4, RawData!$M$2:$M$878, "<"&N4) | Q4: =AVERAGEIFS(RawData!$K$2:$K$878, RawData!$M$2:$M$878, ">="&M4, RawData!$M$2:$M$878, "<"&N4)
A5: 다산북스 | B5: =COUNTIF(RawData!$F$2:$F$878, A5) | C5: =AVERAGEIF(RawData!$F$2:$F$878, A5, RawData!$K$2:$K$878) | D5: =AVERAGEIF(RawData!$F$2:$F$878, A5, RawData!$M$2:$M$878) | E5: =SUMIF(RawData!$F$2:$F$878, A5, RawData!$L$2:$L$878) | G5: 20000 | H5: 25000 | I5: 2만~2.5만원 | J5: =COUNTIFS(RawData!$H$2:$H$878, ">="&G5, RawData!$H$2:$H$878, "<"&H5) | K5: =AVERAGEIFS(RawData!$K$2:$K$878, RawData!$H$2:$H$878, ">="&G5, RawData!$H$2:$H$878, "<"&H5) | M5: 9.5 | N5: 10.1 | O5: 9.5점초과 | P5: =COUNTIFS(RawData!$M$2:$M$878, ">="&M5, RawData!$M$2:$M$878, "<"&N5) | Q5: =AVERAGEIFS(RawData!$K$2:$K$878, RawData!$M$2:$M$878, ">="&M5, RawData!$M$2:$M$878, "<"&N5)
A6: 알에이치코리아(RHK) | B6: =COUNTIF(RawData!$F$2:$F$878, A6) | C6: =AVERAGEIF(RawData!$F$2:$F$878, A6, RawData!$K$2:$K$878) | D6: =AVERAGEIF(RawData!$F$2:$F$878, A6, RawData!$M$2:$M$878) | E6: =SUMIF(RawData!$F$2:$F$878, A6, RawData!$L$2:$L$878) | G6: 25000 | H6: 30000 | I6: 2.5만~3만원 | J6: =COUNTIFS(RawData!$H$2:$H$878, ">="&G6, RawData!$H$2:$H$878, "<"&H6) | K6: =AVERAGEIFS(RawData!$K$2:$K$878, RawData!$H$2:$H$878, ">="&G6, RawData!$H$2:$H$878, "<"&H6)
A7: 21세기북스 | B7: =COUNTIF(RawData!$F$2:$F$878, A7) | C7: =AVERAGEIF(RawData!$F$2:$F$878, A7, RawData!$K$2:$K$878) | D7: =AVERAGEIF(RawData!$F$2:$F$878, A7, RawData!$M$2:$M$878) | E7: =SUMIF(RawData!$F$2:$F$878, A7, RawData!$L$2:$L$878) | G7: 30000 | H7: 999999 | I7: 3만원 초과 | J7: =COUNTIFS(RawData!$H$2:$H$878, ">="&G7, RawData!$H$2:$H$878, "<"&H7) | K7: =AVERAGEIFS(RawData!$K$2:$K$878, RawData!$H$2:$H$878, ">="&G7, RawData!$H$2:$H$878, "<"&H7)
A8: 쌤앤파커스 | B8: =COUNTIF(RawData!$F$2:$F$878, A8) | C8: =AVERAGEIF(RawData!$F$2:$F$878, A8, RawData!$K$2:$K$878) | D8: =AVERAGEIF(RawData!$F$2:$F$878, A8, RawData!$M$2:$M$878) | E8: =SUMIF(RawData!$F$2:$F$878, A8, RawData!$L$2:$L$878)
A9: 한국경제신문사(한경비피) | B9: =COUNTIF(RawData!$F$2:$F$878, A9) | C9: =AVERAGEIF(RawData!$F$2:$F$878, A9, RawData!$K$2:$K$878) | D9: =AVERAGEIF(RawData!$F$2:$F$878, A9, RawData!$M$2:$M$878) | E9: =SUMIF(RawData!$F$2:$F$878, A9, RawData!$L$2:$L$878)
A10: 윌북(willbook) | B10: =COUNTIF(RawData!$F$2:$F$878, A10) | C10: =AVERAGEIF(RawData!$F$2:$F$878, A10, RawData!$K$2:$K$878) | D10: =AVERAGEIF(RawData!$F$2:$F$878, A10, RawData!$M$2:$M$878) | E10: =SUMIF(RawData!$F$2:$F$878, A10, RawData!$L$2:$L$878)
A11: 한빛비즈 | B11: =COUNTIF(RawData!$F$2:$F$878, A11) | C11: =AVERAGEIF(RawData!$F$2:$F$878, A11, RawData!$K$2:$K$878) | D11: =AVERAGEIF(RawData!$F$2:$F$878, A11, RawData!$M$2:$M$878) | E11: =SUMIF(RawData!$F$2:$F$878, A11, RawData!$L$2:$L$878)
A12: 에프엔미디어 | B12: =COUNTIF(RawData!$F$2:$F$878, A12) | C12: =AVERAGEIF(RawData!$F$2:$F$878, A12, RawData!$K$2:$K$878) | D12: =AVERAGEIF(RawData!$F$2:$F$878, A12, RawData!$M$2:$M$878) | E12: =SUMIF(RawData!$F$2:$F$878, A12, RawData!$L$2:$L$878)
A13: 국일증권경제연구소 | B13: =COUNTIF(RawData!$F$2:$F$878, A13) | C13: =AVERAGEIF(RawData!$F$2:$F$878, A13, RawData!$K$2:$K$878) | D13: =AVERAGEIF(RawData!$F$2:$F$878, A13, RawData!$M$2:$M$878) | E13: =SUMIF(RawData!$F$2:$F$878, A13, RawData!$L$2:$L$878)
A14: 위즈덤하우스 | B14: =COUNTIF(RawData!$F$2:$F$878, A14) | C14: =AVERAGEIF(RawData!$F$2:$F$878, A14, RawData!$K$2:$K$878) | D14: =AVERAGEIF(RawData!$F$2:$F$878, A14, RawData!$M$2:$M$878) | E14: =SUMIF(RawData!$F$2:$F$878, A14, RawData!$L$2:$L$878)
A15: 부키 | B15: =COUNTIF(RawData!$F$2:$F$878, A15) | C15: =AVERAGEIF(RawData!$F$2:$F$878, A15, RawData!$K$2:$K$878) | D15: =AVERAGEIF(RawData!$F$2:$F$878, A15, RawData!$M$2:$M$878) | E15: =SUMIF(RawData!$F$2:$F$878, A15, RawData!$L$2:$L$878)
A16: 베가북스 | B16: =COUNTIF(RawData!$F$2:$F$878, A16) | C16: =AVERAGEIF(RawData!$F$2:$F$878, A16, RawData!$K$2:$K$878) | D16: =AVERAGEIF(RawData!$F$2:$F$878, A16, RawData!$M$2:$M$878) | E16: =SUMIF(RawData!$F$2:$F$878, A16, RawData!$L$2:$L$878)
A17: 미래의창 | B17: =COUNTIF(RawData!$F$2:$F$878, A17) | C17: =AVERAGEIF(RawData!$F$2:$F$878, A17, RawData!$K$2:$K$878) | D17: =AVERAGEIF(RawData!$F$2:$F$878, A17, RawData!$M$2:$M$878) | E17: =SUMIF(RawData!$F$2:$F$878, A17, RawData!$L$2:$L$878)
A18: 동양북스(동양books) | B18: =COUNTIF(RawData!$F$2:$F$878, A18) | C18: =AVERAGEIF(RawData!$F$2:$F$878, A18, RawData!$K$2:$K$878) | D18: =AVERAGEIF(RawData!$F$2:$F$878, A18, RawData!$M$2:$M$878) | E18: =SUMIF(RawData!$F$2:$F$878, A18, RawData!$L$2:$L$878)
A19: 비즈니스북스 | B19: =COUNTIF(RawData!$F$2:$F$878, A19) | C19: =AVERAGEIF(RawData!$F$2:$F$878, A19, RawData!$K$2:$K$878) | D19: =AVERAGEIF(RawData!$F$2:$F$878, A19, RawData!$M$2:$M$878) | E19: =SUMIF(RawData!$F$2:$F$878, A19, RawData!$L$2:$L$878)
... A21: 인플루엔셜 | B21: =COUNTIF(RawData!$F$2:$F$878, A21) | C21: =AVERAGEIF(RawData!$F$2:$F$878, A21, RawData!$K$2:$K$878) | D21: =AVERAGEIF(RawData!$F$2:$F$878, A21, RawData!$M$2:$M$878) | E21: =SUMIF(RawData!$F$2:$F$878, A21, RawData!$L$2:$L$878)

Sheet RawData
A1: 상품번호 | B1: 순위 | C1: 도서명 | D1: 부제목 | E1: 저자 | F1: 출판사 | G1: 출판일 | H1: 정가 | I1: 할인가 | J1: 할인율 | K1: 판매지수 | L1: 리뷰건수 | M1: 평점 | N1: 태그 | O1: 이미지URL
A2: 190813759 | B2: 1 | C2: 나의 첫 번째 부동산 교과서 | E2: 송희구 | F2: 서삼독 | G2: 2026년 06월 | H2: 23000 | I2: 20700 | J2: 10 | K2: 168537 | L2: 44 | M2: 9.3 | N2: #부동산투자, #부동산전망, #부동산공부, #부동산재테크, #부동산투자방법 | O2: https://image.yes24.com/goods/190813759/L
A3: 190811719 | B3: 2 | C3: 부의 갈림길 | D3: 대전환의 시작, 다시 쓰는 투자 포트폴리오 | E3: 오건영 | F3: 포레스트북스 | G3: 2026년 06월 | H3: 27000 | I3: 24300 | J3: 10 | K3: 155631 | L3: 61 | M3: 9.9 | N3: #이달의주목신간, #돈구경시켜드릴게, #부자되는법, #성공하고싶다면, #돈이란무엇인가 | O3: https://image.yes24.com/goods/190811719/L
A4: 184337755 | B4: 3 | C4: 주식 투자를 잘한다는 것 | D4: 39세 파이어 육과장, 시장의 변동성을 압도적 수익으로 바꾼 투자 기록 | E4: 육과장 | F4: 노티스 | G4: 2026년 04월 | H4: 22000 | I4: 19800 | J4: 10 | K4: 109503 | L4: 87 | M4: 9.8 | N4: #성장주찾기, #그래제본소, #주식투자입문, #주식투자, #주식초보 | O4: https://image.yes24.com/goods/184337755/L
A5: 193154549 | B5: 4 | C5: 독하게 돈 공부 | D5: 10년 뒤 미래를 바꾸는 유일한 방법 | E5: 박소연 | F5: 메이븐 | G5: 2026년 07월 | H5: 23000 | I5: 20700 | J5: 10 | K5: 4878 | L5: 1 | M5: 8 | O5: https://image.yes24.com/goods/193154549/L
A6: 148032819 | B6: 5 | C6: 박곰희 연금 부자 수업 | D6: 4개의 통장으로 월 300만 원 만들기 | E6: 박곰희 | F6: 인플루엔셜 | G6: 2025년 06월 | H6: 21000 | I6: 18900 | J6: 10 | K6: 563742 | L6: 490 | M6: 9.7 | N6: #은퇴준비, #경제적자유, #똑똑하게투자하기, #노후대비 | O6: https://image.yes24.com/goods/148032819/L
A7: 193352152 | B7: 6 | C7: 적정 주가 가치투자 법칙 | D7: 모든 주식에 통하는 가장 확실하고 지속가능한 반교수의 투자 시스템 | E7: 이주택 | F7: 길벗 | G7: 2026년 07월 | H7: 18800 | I7: 16920 | J7: 10 | K7: 24000 | L7: 5 | M7: 10 | O7: https://image.yes24.com/goods/193352152/L
A8: 172574653 | B8: 7 | C8: 돈의 심리학 (50만 부 기념 뉴 에디션) | D8: 당신은 왜 부자가 되지 못했는가 | E8: 모건 하우절 저/이지연 역 | F8: 인플루엔셜 | G8: 2026년 01월 | H8: 24800 | I8: 22320 | J8: 10 | K8: 139710 | L8: 1317 | M8: 9.4 | N8: #투자전략, #주식초보, #주식투자입문, #주식투자, #부자되는법 | O8: https://image.yes24.com/goods/172574653/L
A9: 59580017 | B9: 8 | C9: 생각에 관한 생각 | D9: 우리의 행동을 지배하는 생각의 반란 | E9: 대니얼 카너먼 저/이창신 역 | F9: 김영사 | G9: 2018년 03월 | H9: 29800 | I9: 26820 | J9: 10 | K9: 76650 | L9: 397 | M9: 9.3 | N9: #월간개발자_추천도서, #2021우량투자서35선, #책읽아웃, #잠시쉼표, #인간심리 | O9: https://image.yes24.com/goods/59580017/L
A10: 192875105 | B10: 9 | C10: 사라지는 돈, 살아남는 돈, 불어나는 돈 | D10: 데이터로 보는 넥스트 코스피 투자 전략 | E10: 김효진 | F10: 페이지2북스 | G10: 2026년 07월 | H10: 21000 | I10: 18900 | J10: 10 | K10: 17871 | L10: 4 | M10: 10 | O10: https://image.yes24.com/goods/192875105/L
A11: 192722605 | B11: 10 | C11: 복합불황 2027~2030 | D11: 바젤 Ⅲ 엔드게임 이후, 질식의 5년 | E11: 박홍기 | F11: 바른북스 | G11: 2026년 06월 | H11: 24000 | I11: 21600 | J11: 10 | K11: 49995 | L11: 35 | M11: 10 | O11: https://image.yes24.com/goods/192722605/L
A12: 124999476 | B12: 11 | C12: 불변의 법칙 | D12: 절대 변하지 않는 것들에 대한 23가지 이야기 | E12: 모건 하우절 저/이수경 역 | F12: 서삼독 | G12: 2024년 02월 | H12: 25000 | I12: 22500 | J12: 10 | K12: 94503 | L12: 781 | M12: 9.5 | N12: #2026_리딩런_마라톤코스추천, #올해의책, #부자되는법, #부자만들기, #돈좀벌어보자 | O12: https://image.yes24.com/goods/124999476/L
A13: 101875887 | B13: 12 | C13: 라오어의 미국주식 무한매수법 | D13: 레버리지가 아니면 평범한 인생을 바꿀 수 없다 | E13: 라오어 | F13: 알키 | G13: 2021년 06월 | H13: 16000 | I13: 14400 | J13: 10 | K13: 94869 | L13: 209 | M13: 9 | N13: #미국주식, #크레마클럽에있어요 | O13: https://image.yes24.com/goods/101875887/L
A14: 192962553 | B14: 13 | C14: 부富의 알고리즘 | E14: 염규남 | F14: 북랩 | G14: 2026년 07월 | H14: 20000 | I14: 18000 | J14: 10 | K14: 1542 | L14: 0 | M14: 0 | O14: https://image.yes24.com/goods/192962553/L
A15: 112323962 | B15: 14 | C15: 라오어의 미국주식 밸류 리밸런싱 | D15: 레버리지가 아니면 평범한 인생을 바꿀 수 없다 | E15: 라오어 | F15: 알키 | G15: 2022년 08월 | H15: 18000 | I15: 16200 | J15: 10 | K15: 80004 | L15: 141 | M15: 8.6 | N15: #크레마클럽에있어요 | O15: https://image.yes24.com/goods/112323962/L
A16: 192990607 | B16: 15 | C16: 주식은 미국의 전략을 따라 움직인다 | D16: 패권 전쟁이 만드는 부의 지도 | E16: 소현철 | F16: 황금부엉이 | G16: 2026년 07월 | H16: 24000 | I16: 21600 | J16: 10 | K16: 3240 | L16: 2 | M16: 10 | O16: https://image.yes24.com/goods/192990607/L
A17: 180975910 | B17: 16 | C17: 딴딴한 투자를 위한 주식투자 교과서 | E17: 정규준 | F17: 애덤스미스 | G17: 2026년 03월 | H17: 25000 | I17: 22500 | J17: 10 | K17: 80412 | L17: 104 | M17: 9.7 | N17: #투자심리, #개미일기, #주식투자입문, #슈퍼개미 | O17: https://image.yes24.com/goods/180975910/L
A18: 182424060 | B18: 17 | C18: 박태웅의 AI 강의 2026 | D18: 인공지능 진화의 가속화부터 AI 기본사회와 일자리의 미래까지 멈추지 않고 인간 세계를 압도하는 새로운 지능의 모든 것 | E18: 박태웅 | F18: 한빛비즈 | G18: 2026년 03월 | H18: 23000 | I18: 20700 | J18: 10 | K18: 77622 | L18: 98 | M18: 9.6 | N18: #경제이야기, #경제전망, #내인생첫경제공부, #인공지능, #인공지능교육 | O18: https://image.yes24.com/goods/182424060/L
A19: 172506508 | B19: 18 | C19: 돈의 방정식 | D19: 돈을 지위와 성공의 기준, 그 이상으로 다루기 위한 21가지 이야기 | E19: 모건 하우절 저/박영준 역 | F19: 서삼독 | G19: 2026년 01월 | H19: 28000 | I19: 25200 | J19: 10 | K19: 142869 | L19: 204 | M19: 9.3 | N19: #2026_SERICEO_휴가철추천도서, #2026_리딩런_마라톤코스추천, #돈이란무엇인가, #돈관념, #돈을아십니까 | O19: https://image.yes24.com/goods/172506508/L
A20: 142763252 | B20: 19 | C20: 돈미새 | E20: 정윤진 | F20: 모티브 | G20: 2025년 02월 | H20: 18800 | I20: 16920 | J20: 10 | K20: 2184 | L20: 72 | M20: 9.3 | O20: https://image.yes24.com/goods/142763252/L
A21: 189608229 | B21: 20 | C21: 천만 원으로 시작해 매달 500만 원 받는 ETF 월배당머신 | D21: AI 시대에도 살아남는 배당 ETF 실전 투자 | E21: 평온, 김지형 | F21: 이나우스북스 | G21: 2026년 05월 | H21: 23000 | I21: 20700 | J21: 10 | K21: 39567 | L21: 121 | M21: 9.9 | N21: #ETF투자, #주식고수 | O21: https://image.yes24.com/goods/189608229/L
A22: 184261820 | B22: 21 | C22: AI, 신의 탄생 인간의 종말 | D22: 초지능의 탄생, 그 이후 벌어질 일들 | E22: 엘리에저 유드코스키, 네이트 소아레스 저/고영훈 역 | F22: 상상스퀘어 | G22: 2026년 04월 | H22: 22000 | I22: 19800 | J22: 10 | K22: 52545 | L22: 33 | M22: 9.7 | N22: #2026_SERICEO_휴가철추천도서, #디지털경제, #세계경제, #경제이야기, #경제전망 | O22: https://image.yes24.com/goods/184261820/L
A23: 192465044 | B23: 22 | C23: 강남 아파트는 못 샀어도, 좋은 주식은 살 수 있다 | E23: 채부심(채상욱) | F23: 커넥티드그라운드 | G23: 2026년 06월 | H23: 22000 | I23: 19800 | J23: 10 | K23: 42096 | L23: 3 | M23: 10 | O23: https://image.yes24.com/goods/192465044/L
A24: 189627438 | B24: 23 | C24: 주도주 사이클 절대 법칙 | D24: 지수를 넘어 압도적 수익을 이끄는 투자 불패 공식 | E24: 한규범 | F24: 부키 | G24: 2026년 05월 | H24: 22000 | I24: 19800 | J24: 10 | K24: 36765 | L24: 39 | M24: 9.9 | N24: #성장주찾기, #주식투자입문, #주식투자, #주식초보, #주식고수 | O24: https://image.yes24.com/goods/189627438/L
A25: 192151426 | B25: 24 | C25: 정프로의 한없이 가벼운 경제 상식 | E25: 정영진 | F25: 저녁달 | G25: 2026년 06월 | H25: 20000 | I25: 18000 | J25: 10 | K25: 10050 | L25: 3 | M25: 10 | O25: https://image.yes24.com/goods/192151426/L
A26: 191535368 | B26: 25 | C26: 슈퍼개미 이정윤의 성장주 집중 투자 | D26: 앞으로 10년, 10배 수익을 불러오는 8대 메가트렌트 | E26: 이정윤 | F26: 베가북스 | G26: 2026년 06월 | H26: 25000 | I26: 22500 | J26: 10 | K26: 88428 | L26: 19 | M26: 10 | N26: #성장주찾기, #똑똑하게투자하기, #주식매매법, #부자되는법, #주식투자 | O26: https://image.yes24.com/goods/191535368/L
A27: 11081680 | B27: 26 | C27: 자본주의 | D27: 쉬지 않고 일하는데 나는 왜 이렇게 살기 힘든가 | E27: EBS 〈자본주의〉제작팀, 정지은, 고희정 저/EBS MEDIA 기획 | F27: 가나출판사 | G27: 2013년 09월 | H27: 22000 | I27: 19800 | J27: 10 | K27: 88518 | L27: 1042 | M27: 9.5 | N27: #크레마클럽에있어요, #북클러버의선택, #금융문맹탈출 | O27: https://image.yes24.com/goods/11081680/L
A28: 192468921 | B28: 27 | C28: 주식 투자의 그릇 | D28: 90세 현역 트레이더 시게루 할아버지의 일대일 부자 수업 | E28: 후지모토 시게루 저/박선영 역 | F28: 다산북스 | G28: 2026년 06월 | H28: 20000 | I28: 18000 | J28: 10 | K28: 18420 | L28: 32 | M28: 9.8 | O28: https://image.yes24.com/goods/192468921/L
A29: 184277605 | B29: 28 | C29: 부의 사다리에 올라타라 | D29: 당신의 자산을 확실하게 늘리는 6가지 방법 | E29: 닉 매기울리 저/박슬라 역 | F29: 알에이치코리아(RHK) | G29: 2026년 04월 | H29: 23000 | I29: 20700 | J29: 10 | K29: 47025 | L29: 23 | M29: 9.8 | N29: #고수의투자원칙, #투자이론, #투자가이드, #투자와회계, #성공투자서 | O29: https://image.yes24.com/goods/184277605/L
A30: 175467785 | B30: 29 | C30: 주식투자 무작정 따라하기 | D30: 100만 왕초보가 감동한 최고의 주식투자 입문서 | E30: 윤재수 | F30: 길벗 | G30: 2026년 01월 | H30: 25000 | I30: 22500 | J30: 10 | K30: 75006 | L30: 32 | M30: 9.8 | N30: #주식투자입문, #주식초보, #주식매매법 | O30: https://image.yes24.com/goods/175467785/L
A31: 159167901 | B31: 30 | C31: 3줄의 글로 수익을 만드는 스레드 운영법 | D31: 스레드 브랜딩·마케팅·수익화 실전 전략 | E31: 이동영 | F31: 한빛미디어 | G31: 2025년 10월 | H31: 20000 | I31: 18000 | J31: 10 | K31: 13386 | L31: 39 | M31: 9.6 | O31: https://image.yes24.com/goods/159167901/L
A32: 122532297 | B32: 31 | C32: 돈, 뜨겁게 사랑하고 차갑게 다루어라 | E32: 앙드레 코스톨라니 저/한윤진 역 | F32: 미래의창 | G32: 2023년 09월 | H32: 15000 | I32: 13500 | J32: 10 | K32: 38145 | L32: 139 | M32: 9.4 | O32: https://image.yes24.com/goods/122532297/L
A33: 7240183 | B33: 32 | C33: 최고의 주식 최적의 타이밍 | E33: 윌리엄 J. 오닐 | F33: 굿모닝북스 | G33: 2012년 06월 | H33: 19800 | I33: 17820 | J33: 10 | K33: 27168 | L33: 190 | M33: 9.3 | O33: https://image.yes24.com/goods/7240183/L
A34: 192558039 | B34: 33 | C34: 주식투자 불패의 법칙 | D34: 부의 체급을 바꾸는 고수익 투자의 정석 | E34: 조진표 | F34: 오아시스 | G34: 2026년 07월 | H34: 21000 | I34: 18900 | J34: 10 | K34: 18816 | L34: 6 | M34: 10 | O34: https://image.yes24.com/goods/192558039/L
A35: 182639140 | B35: 34 | C35: 평생 월 500만 원 받는 월배당 ETF | D35: 한 달에 두 번 따박따박 월급받는 투자법 | E35: 배당의만장 | F35: 노티스 | G35: 2026년 03월 | H35: 23000 | I35: 20700 | J35: 10 | K35: 49095 | L35: 50 | M35: 9.9 | N35: #투자트렌드, #투자가이드, #똑똑하게투자하기, #투자전략, #ETF투자 | O35: https://image.yes24.com/goods/182639140/L
A36: 154827889 | B36: 35 | C36: 손자병법 | D36: 이겨놓고 싸우는 인생의 지혜 | E36: 손자 저/소준섭 역 | F36: 현대지성 | G36: 2025년 10월 | H36: 13000 | I36: 11700 | J36: 10 | K36: 147624 | L36: 277 | M36: 9.7 | N36: #위기대응, #동양고전, #리더십, #동양철학, #불멸의고전 | O36: https://image.yes24.com/goods/154827889/L
A37: 103990890 | B37: 36 | C37: 제로 투 원 (10주년 기념판) | D37: 스탠퍼드대학교 스타트업 최고 명강의 | E37: 피터 틸, 블레이크 매스터스 저/이지연 역 | F37: 한국경제신문사(한경비피) | G37: 2025년 04월 | H37: 18000 | I37: 16200 | J37: 10 | K37: 82614 | L37: 205 | M37: 9.7 | N37: #미래경영, #경영철학, #경영전략 | O37: https://image.yes24.com/goods/103990890/L
A38: 192664351 | B38: 37 | C38: 1억부터는 포트폴리오다 | D38: 연기금처럼 투자하라 | E38: 신환종 | F38: 에프엔미디어 | G38: 2026년 07월 | H38: 25000 | I38: 22500 | J38: 10 | K38: 5604 | L38: 2 | M38: 10 | O38: https://image.yes24.com/goods/192664351/L
A39: 192130777 | B39: 38 | C39: 나는 성장주 투자로 40에 은퇴했다 | D39: 5천만 원으로 17억 만든 수익 불패 황금 공식 | E39: 파돌댁 | F39: 체인지업 | G39: 2026년 07월 | H39: 23000 | I39: 20700 | J39: 10 | K39: 4692 | L39: 13 | M39: 10 | O39: https://image.yes24.com/goods/192130777/L
A40: 169902356 | B40: 39 | C40: 캔들차트 하나로 끝내는 추세추종 투자 | D40: 주식 매수 매도 타이밍을 읽는 눈 | E40: 성승현 | F40: 포르체 | G40: 2026년 01월 | H40: 25000 | I40: 22500 | J40: 10 | K40: 96099 | L40: 70 | M40: 8.7 | N40: #차트공부, #주식차트, #주식투자, #주식매매법 | O40: https://image.yes24.com/goods/169902356/L
...

Sheet 이레미디어
A1: 순위 | B1: 도서명 | C1: 저자 | D1: 출판사 | E1: 출판일 | F1: 정가 | G1: 할인가 | H1: 판매지수 | I1: 리뷰건수 | J1: 평점 | K1: 태그
A2: 84 | B2: 손실은 짧게 수익은 길게 | C2: 깡토 | D2: 이레미디어 | E2: 2025년 05월 | F2: 25000 | G2: 22500 | H2: 26514 | I2: 136 | J2: 9.3 | K2: #크레마클럽에있어요, #고수의투자원칙, #똑똑하게투자하기, #투자전략, #살려주식시오
A3: 89 | B3: 터틀 트레이딩 | C3: 마이클 코벨 저/오인석 역 | D3: 이레미디어 | E3: 2019년 05월 | F3: 19500 | G3: 17550 | H3: 14205 | I3: 65 | J3: 8.3 | K3: #크레마클럽에있어요
A4: 107 | B4: 이동 평균선 투자법 | C4: 고지로 강사 저/김정환 역 | D4: 이레미디어 | E4: 2024년 05월 | F4: 17000 | G4: 15300 | H4: 24567 | I4: 181 | J4: 9.2 | K4: #크레마클럽에있어요, #주식초보, #투자전략, #똑똑하게투자하기, #주식고수
A5: 137 | B5: 차트투자 처음공부 | C5: 김정환 | D5: 이레미디어 | E5: 2026년 03월 | F5: 24000 | G5: 21600 | H5: 4278 | I5: 36 | J5: 9.7 | K5: #크레마클럽에있어요
A6: 141 | B6: 절대수익 우량주 매매법 | C6: 성경호 | D6: 이레미디어 | E6: 2026년 02월 | F6: 39000 | G6: 35100 | H6: 27357 | I6: 92 | J6: 9.6 | K6: #크레마클럽에있어요, #그래제본소
A7: 152 | B7: 추세추종 투자전략 | C7: 마이클 코벨 저/김태훈 역 | D7: 이레미디어 | E7: 2023년 07월 | F7: 18500 | G7: 16650 | H7: 2232 | I7: 19 | J7: 9.7
A8: 158 | B8: 윌리엄 오닐의 성공 투자 법칙 | C8: 윌리엄 오닐 저/김태훈 역 | D8: 이레미디어 | E8: 2021년 07월 | F8: 17000 | G8: 15300 | H8: 2592 | I8: 51 | J8: 9.2 | K8: #크레마클럽에있어요
A9: 174 | B9: 투자는 심리전이다 | C9: 마이클 코벨 저/장진영 역 | D9: 이레미디어 | E9: 2026년 07월 | F9: 25000 | G9: 22500 | H9: 1014 | I9: 1 | J9: 10
A10: 180 | B10: 마틴 츠바이크의 위대한 투자 원칙 | C10: 마틴 츠바이크 저/송미리 역 | D10: 이레미디어 | E10: 2026년 06월 | F10: 22000 | G10: 19800 | H10: 1872 | I10: 18 | J10: 9.8
A11: 201 | B11: 왜 추세추종전략인가 | C11: 마이클 코벨 저/박준형 역 | D11: 이레미디어 | E11: 2026년 03월 | F11: 21000 | G11: 18900 | H11: 2532 | I11: 29 | J11: 9.7
A12: 229 | B12: 빅 트레이더의 주도주 매매법 | C12: 서희파더(이재상) | D12: 이레미디어 | E12: 2024년 12월 | F12: 35000 | G12: 31500 | H12: 18972 | I12: 107 | J12: 8.4 | K12: #크레마클럽에있어요, #돈좀벌어보자, #주식매매법, #주식투자, #주식고수
A13: 247 | B13: 초수익 성장주 투자 | C13: 마크 미너비니 저/김태훈 역/김대현 감수 | D13: 이레미디어 | E13: 2023년 03월 | F13: 25000 | G13: 22500 | H13: 17745 | I13: 244 | J13: 9.5
A14: 252 | B14: 실전 차트 패턴 63 | C14: 윌리엄 자일러 저/김태훈 역 | D14: 이레미디어 | E14: 2022년 08월 | F14: 18500 | G14: 16650 | H14: 4518 | I14: 57 | J14: 8.7 | K14: #크레마클럽에있어요, #주식차트, #차트공부
A15: 253 | B15: 윌리엄 오닐의 이기는 투자 | C15: 윌리엄 오닐 저/이혜경 역 | D15: 이레미디어 | E15: 2022년 07월 | F15: 17500 | G15: 15750 | H15: 3696 | I15: 55 | J15: 9.4
A16: 268 | B16: 기술적 분석 모르고 절대 주식투자 하지 마라 | C16: 잭 슈웨거 저/이은주 역 | D16: 이레미디어 | E16: 2019년 09월 | F16: 21000 | G16: 18900 | H16: 1662 | I16: 43 | J16: 8.6
A17: 271 | B17: 투자를 어떻게 할 것인가 | C17: 모니시 파브라이 저/김인정 역 | D17: 이레미디어 | E17: 2018년 07월 | F17: 18000 | G17: 16200 | H17: 5226 | I17: 147 | J17: 9.1 | K17: #크레마클럽에있어요, #2021우량투자서35선
A18: 279 | B18: 차트의 기술 | C18: 김정환 | D18: 이레미디어 | E18: 2013년 06월 | F18: 22000 | G18: 19800 | H18: 8268 | I18: 345 | J18: 9.5
A19: 330 | B19: 타이밍의 기술 | C19: 제럴드 아펠 저/송미리 역 | D19: 이레미디어 | E19: 2026년 06월 | F19: 27000 | G19: 24300 | H19: 2652 | I19: 19 | J19: 10
A20: 337 | B20: 시장의 마법사들 | C20: 잭 슈웨거 저/송미리 역 | D20: 이레미디어 | E20: 2026년 06월 | F20: 30000 | G20: 27000 | H20: 4050 | I20: 14 | J20: 9.7
A21: 363 | B21: 스트리트 스마트 | C21: 로렌스 A. 코너스, 린다 브래드포드 라쉬케 저/이주영 역 | D21: 이레미디어 | E21: 2026년 05월 | F21: 33000 | G21: 29700 | H21: 2736 | I21: 27 | J21: 9.6 | K21: #주식초보, #해외주식은어떨까, #미국주식, #주식고수, #주식매매법
A22: 459 | B22: 데이 스윙 트레이딩 바이블 | C22: 올리버 벨레즈, 그렉 캐프라 저/송미리 역 | D22: 이레미디어 | E22: 2025년 11월 | F22: 27000 | G22: 24300 | H22: 6972 | I22: 38 | J22: 9.8
A23: 502 | B23: 초보자를 단숨에 고수로 만드는 주식투자 핵심 수업 | C23: 이정윤 | D23: 이레미디어 | E23: 2025년 08월 | F23: 25000 | G23: 22500 | H23: 34446 | I23: 69 | J23: 9.4 | K23: #크레마클럽에있어요, #주식초보, #주식투자입문, #주식투자
A24: 513 | B24: 추세에 관한 6가지 트레이딩 시스템 | C24: 웰스 와일더 저/이주영 역 | D24: 이레미디어 | E24: 2025년 07월 | F24: 23000 | G24: 20700 | H24: 1980 | I24: 18 | J24: 9.4
A25: 565 | B25: 라이어스 포커 | C25: 마이클 루이스 저/장진영 역 | D25: 이레미디어 | E25: 2025년 01월 | F25: 18500 | G25: 16650 | H25: 2640 | I25: 27 | J25: 9
A26: 574 | B26: 시장에서 살아남는 실전 추세매매기법 | C26: 토마스 카 저/김태훈 역 | D26: 이레미디어 | E26: 2024년 12월 | F26: 25000 | G26: 22500 | H26: 1674 | I26: 28 | J26: 9.9
A27: 597 | B27: 챔피언처럼 생각하고 거래하라 | C27: 마크 미너비니 저/송미리 역/김대현 감수 | D27: 이레미디어 | E27: 2024년 08월 | F27: 25000 | G27: 22500 | H27: 13206 | I27: 140 | J27: 9.5 | K27: #크레마클럽에있어요, #주식투자, #성공투자서, #투자전략, #돈좀벌어보자
A28: 610 | B28: cis의 주식 투자 법칙 | C28: cis 저/김정환 역 | D28: 이레미디어 | E28: 2024년 05월 | F28: 18500 | G28: 16650 | H28: 7758 | I28: 66 | J28: 8.1 | K28: #크레마클럽에있어요, #주식초보, #주식투자
A29: 620 | B29: 엘리어트 파동 이론 | C29: 랄프 넬슨 엘리어트 저/Robin Chang, 윤지민 역 | D29: 이레미디어 | E29: 2024년 03월 | F29: 22000 | G29: 19800 | H29: 870 | I29: 22 | J29: 8.5 | K29: #크레마클럽에있어요
A30: 622 | B30: 어느 주식투자자의 회상 | C30: 에드윈 르페브르 저/박성환 역 | D30: 이레미디어 | E30: 2024년 03월 | F30: 16000 | G30: 14400 | H30: 5964 | I30: 49 | J30: 9.4 | K30: #크레마클럽에있어요
A31: 626 | B31: 반도체 제국의 미래 | C31: 정인성 | D31: 이레미디어 | E31: 2024년 02월 | F31: 22000 | G31: 19800 | H31: 3306 | I31: 4 | J31: 9.5
A32: 628 | B32: 미국주식 처음공부 | C32: 수미숨(상의민), 애나정 | D32: 이레미디어 | E32: 2024년 02월 | F32: 22000 | G32: 19800 | H32: 23556 | I32: 144 | J32: 9.7 | K32: #크레마클럽에있어요, #재테크기초, #미국주식
A33: 635 | B33: 추세 매매의 대가들 | C33: 마이클 코벨 저/김태훈 역 | D33: 이레미디어 | E33: 2023년 10월 | F33: 20000 | G33: 18000 | H33: 534 | I33: 24 | J33: 9.2
A34: 642 | B34: 재무제표로 좋은 주식 고르는 법 | C34: 이강연 | D34: 이레미디어 | E34: 2023년 09월 | F34: 22000 | G34: 19800 | H34: 930 | I34: 13 | J34: 9.2
A35: 655 | B35: 채권투자 처음공부 | C35: 포프리라이프(석동민) | D35: 이레미디어 | E35: 2023년 05월 | F35: 21000 | G35: 18900 | H35: 5817 | I35: 187 | J35: 9.6
A36: 665 | B36: 제시 리버모어의 주식투자 바이블 | C36: 제시 리버모어 저/이은주 역 | D36: 이레미디어 | E36: 2023년 03월 | F36: 17500 | G36: 15750 | H36: 10998 | I36: 114 | J36: 9.5
A37: 736 | B37: 실전투자의 비밀 | C37: 김형준 | D37: 이레미디어 | E37: 2021년 06월 | F37: 22000 | G37: 19800 | H37: 6696 | I37: 169 | J37: 9.3 | K37: #크레마클럽에있어요, #고수의투자원칙, #주식투자
A38: 746 | B38: 볼린저 밴드 투자기법 | C38: 존 볼린저 저/신가을 역/김정환 감수 | D38: 이레미디어 | E38: 2021년 01월 | F38: 25000 | G38: 22500 | H38: 10428 | I38: 61 | J38: 9.1
A39: 750 | B39: 타이밍의 마법사들 | C39: 잭 슈웨거 저/김인정 역 | D39: 이레미디어 | E39: 2020년 12월 | F39: 17500 | G39: 15750 | H39: 1044 | I39: 45 | J39: 9.3 | K39: #크레마클럽에있어요
A40: 810 | B40: 거래량으로 투자하라 | C40: 버프 도르마이어 저/신가을 역 | D40: 이레미디어 | E40: 2018년 01월 | F40: 22000 | G40: 19800 | H40: 4110 | I40: 91 | J40: 7.4
...

Sheet 길벗
A1: 순위 | B1: 도서명 | C1: 저자 | D1: 출판사 | E1: 출판일 | F1: 정가 | G1: 할인가 | H1: 판매지수 | I1: 리뷰건수 | J1: 평점 | K1: 태그
A2: 6 | B2: 적정 주가 가치투자 법칙 | C2: 이주택 | D2: 길벗 | E2: 2026년 07월 | F2: 18800 | G2: 16920 | H2: 24000 | I2: 5 | J2: 10
A3: 29 | B3: 주식투자 무작정 따라하기 | C3: 윤재수 | D3: 길벗 | E3: 2026년 01월 | F3: 25000 | G3: 22500 | H3: 75006 | I3: 32 | J3: 9.8 | K3: #주식투자입문, #주식초보, #주식매매법
A4: 47 | B4: 제미나이 주식투자 | C4: 조성호 | D4: 길벗 | E4: 2026년 04월 | F4: 20000 | G4: 18000 | H4: 63324 | I4: 140 | J4: 9.6 | K4: #AI로시작하는투자, #주식투자입문, #주식투자, #주식초보, #주식고수
A5: 54 | B5: 연금 투자 무작정 따라하기 | C5: 김성일 | D5: 길벗 | E5: 2026년 05월 | F5: 24000 | G5: 21600 | H5: 14781 | I5: 24 | J5: 9.9
A6: 104 | B6: 주식투자 단기 트레이딩의 정석 | C6: 강창권 | D6: 길벗 | E6: 2025년 09월 | F6: 33000 | G6: 29700 | H6: 32022 | I6: 62 | J6: 9.5 | K6: #단기투자, #주식매매법
A7: 108 | B7: 처음부터 시작하는 주식투자 단타전략 | C7: 홍인기 | D7: 길벗 | E7: 2023년 12월 | F7: 21000 | G7: 18900 | H7: 37392 | I7: 342 | J7: 8.4 | K7: #주식투자입문, #주식투자
A8: 235 | B8: 채권 투자 무작정 따라하기 | C8: 서준식, 양진영, 서지혜 | D8: 길벗 | E8: 2024년 02월 | F8: 27500 | G8: 24750 | H8: 4878 | I8: 51 | J8: 9.7
A9: 241 | B9: 자동화 마케팅 무작정 따라하기 | C9: 신태순, 조수현 | D9: 길벗 | E9: 2023년 09월 | F9: 22000 | G9: 19800 | H9: 222 | I9: 21 | J9: 9.4 | K9: #자동화기술, #파이프라인으로자동화, #SNS마케팅, #마케팅이란, #디지털마케팅
A10: 259 | B10: 심리투자 불변의 법칙 | C10: 마크 더글러스 저/이진원 역 | D10: 길벗 | E10: 2021년 12월 | F10: 20000 | G10: 18000 | H10: 24087 | I10: 88 | J10: 8.6 | K10: #주식투자입문, #주식투자, #투자트렌드, #투자이론
A11: 286 | B11: AI 영상 제작 | C11: 문수민, 민지영, 신호진, 강경희, 앤미디어 | D11: 길벗 | E11: 2026년 07월 | F11: 27000 | G11: 24300 | H11: 360 | I11: 2 | J11: 10
A12: 292 | B12: 잼비의 첫 재테크 | C12: 잼비 | D12: 길벗 | E12: 2026년 07월 | F12: 22000 | G12: 19800 | H12: 480 | I12: 0 | J12: 0
A13: 409 | B13: 달러 투자 무작정 따라하기 | C13: 박성현 | D13: 길벗 | E13: 2026년 02월 | F13: 25000 | G13: 22500 | H13: 6252 | I13: 29 | J13: 9.9
A14: 422 | B14: 부동산 경매 무작정 따라하기 | C14: 이현정 | D14: 길벗 | E14: 2026년 01월 | F14: 25000 | G14: 22500 | H14: 8790 | I14: 53 | J14: 9.8 | K14: #내집마련, #부동산투자방법
A15: 489 | B15: 부동산 투자 무작정 따라하기 | C15: 제네시스박, 박성혜(훨훨), 강연옥(플팩) | D15: 길벗 | E15: 2025년 09월 | F15: 24000 | G15: 21600 | H15: 13890 | I15: 51 | J15: 9.8
A16: 505 | B16: 만화 경제학 강의 | C16: 조립식, 조윤형 | D16: 길벗 | E16: 2025년 07월 | F16: 18000 | G16: 16200 | H16: 1224 | I16: 19 | J16: 10
A17: 545 | B17: 한 권으로 끝내는 개인사업자 절세 공부 | C17: 한지온 | D17: 길벗 | E17: 2025년 03월 | F17: 19000 | G17: 18050 | H17: 1338 | I17: 16 | J17: 9.3
A18: 559 | B18: 월급쟁이 재테크 상식사전 | C18: 우용표 | D18: 길벗 | E18: 2025년 02월 | F18: 19800 | G18: 17820 | H18: 9333 | I18: 43 | J18: 9.5 | K18: #똑똑하게투자하기, #주식투자, #직장인재테크, #재테크의기본
A19: 595 | B19: 아는 만큼 보이는 AI | C19: 최기원 | D19: 길벗 | E19: 2024년 08월 | F19: 19000 | G19: 17100 | H19: 1020 | I19: 23 | J19: 9.7 | K19: #생성형AI, #챗GPT, #딥러닝, #머신러닝, #인공지능
A20: 607 | B20: 원칙으로 수익 내는 단타의 기술 | C20: 원정연(만쥬) | D20: 길벗 | E20: 2024년 05월 | F20: 22000 | G20: 19800 | H20: 14448 | I20: 116 | J20: 8.6 | K20: #성공하고싶다면, #성공스토리, #주식투자
A21: 702 | B21: 차트분석 무작정 따라하기 | C21: 윤재수 | D21: 길벗 | E21: 2022년 02월 | F21: 25000 | G21: 22500 | H21: 20622 | I21: 66 | J21: 9.7 | K21: #주식고수
A22: 755 | B22: 월급으로 시작하는 부동산투자 | C22: 투자가 카일 | D22: 길벗 | E22: 2020년 09월 | F22: 16500 | G22: 14850 | H22: 84 | I22: 39 | J22: 9.7 | K22: #월급으로시작하는, #월급재테크
A23: 785 | B23: 나는 오르는 주식만 산다 | C23: 와조스키 | D23: 길벗 | E23: 2019년 07월 | F23: 16000 | G23: 14400 | H23: 498 | I23: 65 | J23: 7.2 | K23: #주식투자입문, #유튜버, #돈좀벌어보자, #주식투자
A24: 804 | B24: 하루 만에 수익 내는 실전 주식투자 | C24: 강창권 | D24: 길벗 | E24: 2018년 06월 | F24: 20000 | G24: 18000 | H24: 5292 | I24: 114 | J24: 9.1
A25: 813 | B25: 만화 주식투자 무작정 따라하기 | C25: 이금희 저/윤재수 원저 | D25: 길벗 | E25: 2017년 08월 | F25: 14500 | G25: 13050 | H25: 4680 | I25: 77 | J25: 9.3 | K25: #주식초보, #주식투자입문

Sheet 김영사
A1: 순위 | B1: 도서명 | C1: 저자 | D1: 출판사 | E1: 출판일 | F1: 정가 | G1: 할인가 | H1: 판매지수 | I1: 리뷰건수 | J1: 평점 | K1: 태그
A2: 8 | B2: 생각에 관한 생각 | C2: 대니얼 카너먼 저/이창신 역 | D2: 김영사 | E2: 2018년 03월 | F2: 29800 | G2: 26820 | H2: 76650 | I2: 397 | J2: 9.3 | K2: #월간개발자_추천도서, #2021우량투자서35선, #책읽아웃, #잠시쉼표, #인간심리
A3: 105 | B3: 특이점이 온다 | C3: 레이 커즈와일 저/정재승 해제/김명남, 장시형 역/진대제 감수 | D3: 김영사 | E3: 2025년 03월 | F3: 42000 | G3: 37800 | H3: 16467 | I3: 10 | J3: 8.2 | K3: #교양과학, #기계와인간
A4: 106 | B4: 가난한 찰리의 연감 | C4: 찰리 멍거 저/김태훈 역/피터 코프먼 기획 | D4: 김영사 | E4: 2024년 11월 | F4: 33000 | G4: 29700 | H4: 26457 | I4: 209 | J4: 9 | K4: #똑똑하게투자하기, #경제교육, #성공스토리, #금융공부
A5: 109 | B5: 죽은 경제학자의 살아있는 아이디어 | C5: 토드 부크홀츠 저/류현 역/한순구 감수 | D5: 김영사 | E5: 2023년 09월 | F5: 32800 | G5: 29520 | H5: 15543 | I5: 42 | J5: 9.6 | K5: #경제전망
A6: 169 | B6: 장문정의 마케털이 | C6: 장문정 | D6: 김영사 | E6: 2026년 07월 | F6: 20000 | G6: 18000 | H6: 360 | I6: 0 | J6: 0
A7: 474 | B7: 카이스트 미래전략 2026 | C7: KAIST 문술미래전략대학원 미래전략연구센터 | D7: 김영사 | E7: 2025년 09월 | F7: 25000 | G7: 22500 | H7: 3276 | I7: 21 | J7: 9.9 | K7: #2026를예측하다, #트렌드키워드
A8: 563 | B8: 인구는 내 미래를 어떻게 바꾸는가 | C8: 조영태 | D8: 김영사 | E8: 2024년 12월 | F8: 13500 | G8: 12150 | H8: 1230 | I8: 3 | J8: 6.7
A9: 617 | B9: 초저출산은 왜 생겼을까? | C9: 장대익, 장구, 허지원, 송길영, 주경철 저 외 2명 정보 더 보기/감추기 장대익 장구 허지원 송길영 주경철 조영태 서은국 | D9: 김영사 | E9: 2024년 03월 | F9: 16800 | G9: 15120 | H9: 894 | I9: 21 | J9: 9.5
A10: 636 | B10: 경제학이 필요한 순간 | C10: 김현철 | D10: 김영사 | E10: 2023년 09월 | F10: 17800 | G10: 16020 | H10: 2820 | I10: 56 | J10: 8.3 | K10: #세종도서교양부문선정도서
A11: 698 | B11: 노이즈 : 생각의 잡음 | C11: 대니얼 카너먼, 올리비에 시보니, 캐스 선스타인 저/장진영 역/안서원 감수 | D11: 김영사 | E11: 2022년 04월 | F11: 25000 | G11: 22500 | H11: 2592 | I11: 77 | J11: 9.1 | K11: #노벨경제학상수상자, #노벨경제학상, #청년의날추천도서, #경제이야기, #경제전망
A12: 729 | B12: 크래프톤 웨이 | C12: 이기문 | D12: 김영사 | E12: 2021년 07월 | F12: 22000 | G12: 19800 | H12: 4107 | I12: 40 | J12: 9.4 | K12: #성공스토리
A13: 739 | B13: 좋은 기업을 넘어 위대한 기업으로 (20주년 뉴에디션) | C13: 짐 콜린스 저/이무열 역 | D13: 김영사 | E13: 2021년 03월 | F13: 22000 | G13: 19800 | H13: 12648 | I13: 26 | J13: 9.5
A14: 760 | B14: 티핑 포인트 | C14: 말콤 글래드웰 저/김규태 역 | D14: 김영사 | E14: 2020년 09월 | F14: 16800 | G14: 15120 | H14: 2016 | I14: 50 | J14: 9.3
A15: 764 | B15: 빌 캠벨, 실리콘밸리의 위대한 코치 | C15: 에릭 슈미트, 조너선 로젠버그, 앨런 이글 저/김민주, 이엽 역 | D15: 김영사 | E15: 2020년 07월 | F15: 17800 | G15: 16020 | H15: 2832 | I15: 51 | J15: 9.3
A16: 782 | B16: 성과 향상을 위한 코칭 리더십 | C16: 존 휘트모어 저/김영순 역 | D16: 김영사 | E16: 2019년 09월 | F16: 19800 | G16: 17820 | H16: 1941 | I16: 9 | J16: 7.9
A17: 803 | B17: 생각에 관한 생각 프로젝트 | C17: 마이클 루이스 저/이창신 역 | D17: 김영사 | E17: 2018년 07월 | F17: 18500 | G17: 16650 | H17: 846 | I17: 58 | J17: 8.9
A18: 820 | B18: 코액티브 코칭 | C18: 헨리 킴지하우스, 카렌 킴지하우스, 필립 샌달, 로라 휘트워스 공저 / 김영순, 임광수 공역 | D18: 김영사 | E18: 2016년 11월 | F18: 14000 | G18: 12600 | H18: 648 | I18: 21 | J18: 9.5
A19: 822 | B19: 성과를 내고 싶으면 실행하라 | C19: 크리스 맥체스니, 숀 코비, 짐 헐링 공저 / 이창신 역 / 김경섭 감수 | D19: 김영사 | E19: 2016년 03월 | F19: 18000 | G19: 16200 | H19: 7596 | I19: 261 | J19: 9.9
A20: 840 | B20: 나는 이렇게 될 것이다 | C20: 구본형 | D20: 김영사 | E20: 2013년 09월 | F20: 13800 | G20: 12420 | H20: 4560 | I20: 66 | J20: 9.4
A21: 855 | B21: 물건 이야기 THE STORY OF STUFF | C21: 애니 레너드 저/김승진 역 | D21: 김영사 | E21: 2011년 05월 | F21: 16000 | G21: 14400 | H21: 252 | I21: 40 | J21: 9

Sheet 다산북스
A1: 순위 | B1: 도서명 | C1: 저자 | D1: 출판사 | E1: 출판일 | F1: 정가 | G1: 할인가 | H1: 판매지수 | I1: 리뷰건수 | J1: 평점 | K1: 태그
A2: 27 | B2: 주식 투자의 그릇 | C2: 후지모토 시게루 저/박선영 역 | D2: 다산북스 | E2: 2026년 06월 | F2: 20000 | G2: 18000 | H2: 18420 | I2: 32 | J2: 9.8
A3: 43 | B3: 왜 일하는가 | C3: 이나모리 가즈오 저/김윤경 역 | D3: 다산북스 | E3: 2021년 04월 | F3: 18000 | G3: 16200 | H3: 87099 | I3: 320 | J3: 8.7 | K3: #왜일하는가, #사회초년생, #신입사원, #직장인공감, #성공과성장
A4: 58 | B4: 주식 투자의 기쁨 | C4: 후지모토 시게루 | D4: 다산북스 | E4: 2025년 08월 | F4: 19800 | G4: 17820 | H4: 90180 | I4: 120 | J4: 9.1 | K4: #주식고수, #주식투자입문, #주식투자
A5: 62 | B5: 레버리지 | C5: 롭 무어 저/김유미 역 | D5: 다산북스 | E5: 2023년 02월 | F5: 18000 | G5: 16200 | H5: 44898 | I5: 422 | J5: 9.1 | K5: #편집자의시대_편집자가만든책
A6: 88 | B6: 입지 센스 | C6: 박성혜(훨훨) | D6: 다산북스 | E6: 2022년 07월 | F6: 20000 | G6: 18000 | H6: 4278 | I6: 173 | J6: 9.4 | K6: #부동산투자
A7: 111 | B7: 부자의 그릇 (블랙 에디션) | C7: 이즈미 마사토 저/김윤수 역 | D7: 다산북스 | E7: 2020년 12월 | F7: 17000 | G7: 15300 | H7: 26496 | I7: 1136 | J7: 9.2 | K7: #편집자의시대_편집자가만든책, #크레마클럽에있어요, #돈좀벌어보자, #돈이란무엇인가, #돈구경시켜드릴게
A8: 219 | B8: 주식시장을 이기는 작은 책 | C8: 조엘 그린블라트 저/안진환 역/이상건 감수 | D8: 다산북스 | E8: 2025년 08월 | F8: 22000 | G8: 19800 | H8: 7014 | I8: 27 | J8: 9.6 | K8: #크레마클럽에있어요
A9: 239 | B9: 100일 아침 습관의 기적 | C9: 켈리 최 | D9: 다산북스 | E9: 2023년 11월 | F9: 19000 | G9: 17100 | H9: 3084 | I9: 159 | J9: 9.6 | K9: #습관의힘
A10: 261 | B10: 왜 리더인가 | C10: 이나모리 가즈오 저/김윤경 역 | D10: 다산북스 | E10: 2021년 05월 | F10: 16000 | G10: 14400 | H10: 7083 | I10: 68 | J10: 8.9 | K10: #성공하고싶다면, #리더십, #경영수업
A11: 266 | B11: 주식하는 마음 | C11: 홍진채 | D11: 다산북스 | E11: 2026년 02월 | F11: 22000 | G11: 19800 | H11: 16536 | I11: 135 | J11: 9.1 | K11: #크레마클럽에있어요
A12: 305 | B12: 제너레이션 AI | C12: 맷 브리턴 저/조주희 역 | D12: 다산북스 | E12: 2026년 07월 | F12: 22000 | G12: 19800 | H12: 1158 | I12: 14 | J12: 9.7
A13: 318 | B13: 언노우너스 | C13: 윤상윤 | D13: 다산북스 | E13: 2026년 06월 | F13: 20000 | G13: 18000 | H13: 17250 | I13: 23 | J13: 9.8
A14: 712 | B14: 웰씽킹 WEALTHINKING | C14: 켈리 최 | D14: 다산북스 | E14: 2021년 11월 | F14: 18000 | G14: 16200 | H14: 3564 | I14: 1305 | J14: 9.4 | K14: #끌어당김, #인생지침서, #올해의책, #성공하고싶다면, #세계여성의날
A15: 723 | B15: 왜 사업하는가 | C15: 이나모리 가즈오 저/김지영 역 | D15: 다산북스 | E15: 2021년 08월 | F15: 16000 | G15: 14400 | H15: 3612 | I15: 43 | J15: 9.1 | K15: #편집자의시대_편집자추천도서, #오너라오너
A16: 780 | B16: 두려움 없는 조직 | C16: 에이미 에드먼드슨 저/최윤영 역/오승민 감수 | D16: 다산북스 | E16: 2019년 10월 | F16: 18000 | G16: 16200 | H16: 15555 | I16: 74 | J16: 9.5 | K16: #인재야인재, #경영수업, #인재경영, #조직관리, #리더들이읽는책
A17: 792 | B17: 팀 쿡 Tim Cook | C17: 린더 카니 저/안진환 역 | D17: 다산북스 | E17: 2019년 05월 | F17: 25000 | G17: 22500 | H17: 192 | I17: 140 | J17: 9.2 | K17: #CEO는누가되나, #성공하는기업, #성공과성장, #애플
A18: 793 | B18: 결단 | C18: 롭 무어 저/이진원 역 | D18: 다산북스 | E18: 2019년 04월 | F18: 17000 | G18: 15300 | H18: 2184 | I18: 169 | J18: 8.7 | K18: #북클러버의선택, #김미경TV에소개된책, #성공스토리, #부자되는법, #억만장자

Sheet 알에이치코리아(RHK)
A1: 순위 | B1: 도서명 | C1: 저자 | D1: 출판사 | E1: 출판일 | F1: 정가 | G1: 할인가 | H1: 판매지수 | I1: 리뷰건수 | J1: 평점 | K1: 태그
A2: 28 | B2: 부의 사다리에 올라타라 | C2: 닉 매기울리 저/박슬라 역 | D2: 알에이치코리아(RHK) | E2: 2026년 04월 | F2: 23000 | G2: 20700 | H2: 47025 | I2: 23 | J2: 9.8 | K2: #고수의투자원칙, #투자이론, #투자가이드, #투자와회계, #성공투자서
A3: 59 | B3: 엔비디아 젠슨 황, 생각하는 기계 | C3: 스티븐 위트 저/백우진 역 | D3: 알에이치코리아(RHK) | E3: 2025년 05월 | F3: 28000 | G3: 25200 | H3: 44268 | I3: 98 | J3: 9.5 | K3: #유퀴즈온더블럭_자기님들, #크레마클럽에있어요, #올해의책, #리더의이야기, #경영전략
A4: 93 | B4: 달러, 코인, 전쟁 | C4: 고승연, 이동현 | D4: 알에이치코리아(RHK) | E4: 2026년 07월 | F4: 22000 | G4: 19800 | H4: 2979 | I4: 11 | J4: 9.8
A5: 155 | B5: 처음 배우는 주식 차트 | C5: 한재승 | D5: 알에이치코리아(RHK) | E5: 2023년 04월 | F5: 38000 | G5: 34200 | H5: 9798 | I5: 76 | J5: 9.5 | K5: #크레마클럽에있어요
A6: 209 | B6: 부동산은 어떻게 권력이 되었나 | C6: 마이크 버드 저/박세연 역 | D6: 알에이치코리아(RHK) | E6: 2026년 01월 | F6: 25000 | G6: 22500 | H6: 11826 | I6: 34 | J6: 9.6 | K6: #경제이야기, #한국경제, #중국경제, #미래전망, #부동산전망
A7: 326 | B7: 처음 배우는 미국 주식 투자 | C7: 한재승 | D7: 알에이치코리아(RHK) | E7: 2026년 06월 | F7: 38000 | G7: 34200 | H7: 1386 | I7: 12 | J7: 10
A8: 336 | B8: AI 제국의 돈 | C8: 정주용 | D8: 알에이치코리아(RHK) | E8: 2026년 06월 | F8: 25000 | G8: 22500 | H8: 7203 | I8: 15 | J8: 9.9
A9: 537 | B9: 국세청도 모르는 상속 증여의 기술 | C9: 공찬규 | D9: 알에이치코리아(RHK) | E9: 2025년 04월 | F9: 22000 | G9: 19800 | H9: 4926 | I9: 30 | J9: 9.8
A10: 553 | B10: 손자병법 | C10: 시마자키 스스무 저/양지영 역 | D10: 알에이치코리아(RHK) | E10: 2025년 02월 | F10: 17000 | G10: 15300 | H10: 3168 | I10: 21 | J10: 9.7 | K10: #인생후반전, #고전의재해석, #고전읽어주는책, #살면서한번은읽어야할책
A11: 619 | B11: 요즘 팀장의 리더 수업 | C11: 이민영 | D11: 알에이치코리아(RHK) | E11: 2024년 03월 | F11: 18000 | G11: 16200 | H11: 774 | I11: 18 | J11: 9.9
A12: 625 | B12: 컨셉 수업 | C12: 호소다 다카히로 저/지소연, 권희주 역 | D12: 알에이치코리아(RHK) | E12: 2024년 01월 | F12: 22000 | G12: 19800 | H12: 12540 | I12: 103 | J12: 9.6 | K12: #크레마클럽에있어요, #카피라잇잘쓰는법, #성공하는사업의비결, #제품기획자주목, #마케팅전략
A13: 638 | B13: 비즈니스 협상론 | C13: 김병국 | D13: 알에이치코리아(RHK) | E13: 2023년 09월 | F13: 19800 | G13: 17820 | H13: 3810 | I13: 53 | J13: 9.5
A14: 738 | B14: 프리워커스 | C14: 모빌스 그룹 | D14: 알에이치코리아(RHK) | E14: 2021년 04월 | F14: 22000 | G14: 19800 | H14: 756 | I14: 61 | J14: 8.3 | K14: #왜일하는가, #책읽아웃, #예스티비, #행복하게일하기, #일하는방식
A15: 759 | B15: 규칙 없음 | C15: 리드 헤이스팅스, 에린 마이어 저/이경남 역 | D15: 알에이치코리아(RHK) | E15: 2020년 09월 | F15: 30000 | G15: 27000 | H15: 4797 | I15: 168 | J15: 9.3 | K15: #책읽아웃, #오상진북스타그램, #스페셜에디션, #다시보는2020, #열일하는인사팀
A16: 761 | B16: 화폐전쟁 1 달러의 종말 | C16: 쑹훙빙 저/차혜정 역/박한진 감수 | D16: 알에이치코리아(RHK) | E16: 2020년 09월 | F16: 32000 | G16: 28800 | H16: 5478 | I16: 30 | J16: 8.8
A17: 766 | B17: 백만장자 시크릿 | C17: 하브 에커 저/나선숙 역 | D17: 알에이치코리아(RHK) | E17: 2020년 07월 | F17: 18800 | G17: 16920 | H17: 10812 | I17: 278 | J17: 9.5 | K17: #끌어당김, #마인드가답이다, #부자되는법
A18: 800 | B18: 생각이 돈이 되는 순간 | C18: 앨런 가넷 저/이경남 역 | D18: 알에이치코리아(RHK) | E18: 2018년 12월 | F18: 22000 | G18: 19800 | H18: 5226 | I18: 225 | J18: 9.5 | K18: #성공스토리, #부자되는법, #돈좀벌어보자, #창의적사고

Sheet 21세기북스
A1: 순위 | B1: 도서명 | C1: 저자 | D1: 출판사 | E1: 출판일 | F1: 정가 | G1: 할인가 | H1: 판매지수 | I1: 리뷰건수 | J1: 평점 | K1: 태그
A2: 53 | B2: 반드시 돈이 되는 조선주 투자의 법칙 | C2: 엄경아 | D2: 21세기북스 | E2: 2026년 06월 | F2: 22000 | G2: 19800 | H2: 18336 | I2: 14 | J2: 9.3 | K2: #성장주찾기, #투자트렌드, #투자이론, #투자가이드, #투자포인트총정리
A3: 56 | B3: 진보를 위한 주식투자 | C3: 이광수 | D3: 21세기북스 | E3: 2025년 12월 | F3: 22000 | G3: 19800 | H3: 313332 | I3: 231 | J3: 8.7 | K3: #투자전략, #ETF투자, #주식투자입문, #크레마클럽에있어요, #주식매매법
A4: 101 | B4: 피터케이의 이기는 투자 불변의 법칙 | C4: 피터케이 | D4: 21세기북스 | E4: 2026년 04월 | F4: 22000 | G4: 19800 | H4: 45228 | I4: 90 | J4: 9.6 | K4: #크레마클럽에있어요, #그래제본소, #주식투자입문, #투자트렌드, #투자이론
A5: 171 | B5: 둠루프 | C5: 에스와르 S. 프라사드 저/박재영 역 | D5: 21세기북스 | E5: 2026년 07월 | F5: 39900 | G5: 35910 | H5: 450 | I5: 0 | J5: 0
A6: 181 | B6: 포트폴리오 설계 수업 | C6: 임현우 | D6: 21세기북스 | E6: 2026년 06월 | F6: 20000 | G6: 18000 | H6: 14106 | I6: 3 | J6: 10
A7: 405 | B7: 머니하이의 예금 탈출 플랜 | C7: 김형철(머니하이) | D7: 21세기북스 | E7: 2026년 03월 | F7: 22000 | G7: 19800 | H7: 2382 | I7: 9 | J7: 9.6 | K7: #크레마클럽에있어요
A8: 425 | B8: 더 코인 THE COIN | C8: 성상현 | D8: 21세기북스 | E8: 2026년 01월 | F8: 24000 | G8: 21600 | H8: 14208 | I8: 19 | J8: 7.8 | K8: #크레마클럽에있어요, #경제이야기, #투자가이드, #투자전략, #코인투자입문
A9: 473 | B9: 마쓰시타 고노스케 길을 열다 | C9: 마쓰시타 고노스케 저/김정환 역 | D9: 21세기북스 | E9: 2025년 10월 | F9: 22800 | G9: 20520 | H9: 3192 | I9: 39 | J9: 9.8 | K9: #크레마클럽에있어요
A10: 478 | B10: 80/20 법칙 | C10: 리처드 코치 저/공병호 역 | D10: 21세기북스 | E10: 2025년 09월 | F10: 24000 | G10: 21600 | H10: 1710 | I10: 44 | J10: 10
A11: 541 | B11: 이나모리 가즈오, 부러지지 않는 마음 | C11: 이나모리 가즈오 저/이나모리 라이브러리 편저/양준호 역 | D11: 21세기북스 | E11: 2025년 03월 | F11: 22000 | G11: 19800 | H11: 6852 | I11: 15 | J11: 9.6 | K11: #노력, #크레마클럽에있어요
A12: 562 | B12: 애프터 넷플릭스 | C12: 조영신 | D12: 21세기북스 | E12: 2025년 01월 | F12: 22000 | G12: 19800 | H12: 528 | I12: 2 | J12: 10 | K12: #크레마클럽에있어요
A13: 586 | B13: 자취백과사전 | C13: 자취남 저/이승주 감수 | D13: 21세기북스 | E13: 2024년 10월 | F13: 11000 | G13: 9900 | H13: 1068 | I13: 7 | J13: 10 | K13: #유튜버의책, #전세사기예방법, #독립하고싶다
A14: 640 | B14: 일론 머스크 | C14: 월터 아이작슨 저/안진환 역 | D14: 21세기북스 | E14: 2023년 09월 | F14: 38000 | G14: 34200 | H14: 26088 | I14: 253 | J14: 9.5 | K14: #크레마클럽에있어요, #서탐대실, #성공스토리, #혁신가
A15: 697 | B15: 기업은 누구의 것인가 | C15: 이관휘 | D15: 21세기북스 | E15: 2022년 04월 | F15: 18000 | G15: 16200 | H15: 1116 | I15: 50 | J15: 9.8
A16: 732 | B16: 노는 만큼 성공한다 | C16: 김정운 | D16: 21세기북스 | E16: 2021년 06월 | F16: 22000 | G16: 19800 | H16: 1362 | I16: 9 | J16: 9.8 | K16: #성공하고싶다면, #자기관리
A17: 751 | B17: 노희영의 브랜딩 법칙 | C17: 노희영 | D17: 21세기북스 | E17: 2020년 12월 | F17: 22000 | G17: 19800 | H17: 8241 | I17: 117 | J17: 9 | K17: #브랜딩잘하는법, #성공하는사업의비결, #성공하는기업, #성공하고싶다면, #성공의공식

Sheet 쌤앤파커스
A1: 순위 | B1: 도서명 | C1: 저자 | D1: 출판사 | E1: 출판일 | F1: 정가 | G1: 할인가 | H1: 판매지수 | I1: 리뷰건수 | J1: 평점 | K1: 태그
A2: 113 | B2: 돈을 이기는 법 | C2: 성필규 | D2: 쌤앤파커스 | E2: 2013년 04월 | F2: 16000 | G2: 14400 | H2: 12678 | I2: 128 | J2: 9.4 | K2: #크레마클럽에있어요
A3: 228 | B3: 세스 고딘의 전략 수업 | C3: 세스 고딘 저/안진환 역 | D3: 쌤앤파커스 | E3: 2025년 01월 | F3: 23000 | G3: 20700 | H3: 3498 | I3: 74 | J3: 9.1 | K3: #경영바이블, #경영전략, #인생전략
A4: 244 | B4: 보랏빛 소가 온다 | C4: 세스 고딘 저/이주형, 남수영 역 | D4: 쌤앤파커스 | E4: 2023년 07월 | F4: 18000 | G4: 16200 | H4: 10980 | I4: 75 | J4: 9.1
A5: 248 | B5: 장사의 신 : 200쇄 기념 블랙에디션 | C5: 우노 다카시 저/김문정 역 | D5: 쌤앤파커스 | E5: 2023년 01월 | F5: 16000 | G5: 14400 | H5: 6888 | I5: 33 | J5: 9.1
A6: 269 | B6: 마케팅이다 | C6: 세스 고딘 저/김태훈 역 | D6: 쌤앤파커스 | E6: 2019년 03월 | F6: 18000 | G6: 16200 | H6: 11670 | I6: 203 | J6: 8.6 | K6: #크레마클럽에있어요, #마케터는보라, #마케팅이란
A7: 310 | B7: 감정 설계자 | C7: 이동철 | D7: 쌤앤파커스 | E7: 2026년 07월 | F7: 22000 | G7: 19800 | H7: 1209 | I7: 8 | J7: 9.8
A8: 390 | B8: 마케팅 천재의 돈 버는 공식 | C8: 장문정 | D8: 쌤앤파커스 | E8: 2026년 03월 | F8: 20000 | G8: 18000 | H8: 3756 | I8: 33 | J8: 9.7 | K8: #크레마클럽에있어요
A9: 406 | B9: 다시, 초격차 | C9: 권오현 | D9: 쌤앤파커스 | E9: 2026년 03월 | F9: 22000 | G9: 19800 | H9: 24537 | I9: 30 | J9: 9.5 | K9: #2026_SERICEO_휴가철추천도서, #조직관리, #유능한리더되기, #리더들이읽는책
A10: 416 | B10: 2026 한국에 투자하라 | C10: 나탈리 허 | D10: 쌤앤파커스 | E10: 2026년 02월 | F10: 18500 | G10: 16650 | H10: 6186 | I10: 34 | J10: 9.8 | K10: #크레마클럽에있어요
A11: 646 | B11: 있는 공간, 없는 공간 | C11: 유정수 | D11: 쌤앤파커스 | E11: 2023년 06월 | F11: 18000 | G11: 16200 | H11: 1590 | I11: 119 | J11: 9.6 | K11: #마케팅전략, #멋진건축물, #브랜딩잘하는법
A12: 677 | B12: 천 원을 경영하라 | C12: 박정부 | D12: 쌤앤파커스 | E12: 2022년 12월 | F12: 16000 | G12: 14400 | H12: 2202 | I12: 205 | J12: 9.5 | K12: #크레마클럽에있어요, #인생지침서, #성공하고싶다면, #창업할때읽으면좋은책
A13: 771 | B13: 블리츠스케일링 | C13: 크리스 예, 리드 호프먼 저/이영래 역 | D13: 쌤앤파커스 | E13: 2020년 04월 | F13: 22000 | G13: 19800 | H13: 1398 | I13: 63 | J13: 9.3
A14: 795 | B14: 포노 사피엔스 | C14: 최재붕 | D14: 쌤앤파커스 | E14: 2019년 03월 | F14: 16800 | G14: 15120 | H14: 912 | I14: 439 | J14: 8.8 | K14: #MZ세대감성, #국립중앙도서관사서추천, #북클러버의선택, #뭐읽지, #김미경TV에소개된책
A15: 831 | B15: 경영의 모험 | C15: 존 브룩스 저/이충호 역/이동기 감수 | D15: 쌤앤파커스 | E15: 2015년 03월 | F15: 16000 | G15: 14400 | H15: 1716 | I15: 117 | J15: 8.9 | K15: #2PM준호의책장, #빌게이츠추천
A16: 844 | B16: 팔지 마라 사게 하라 | C16: 장문정 | D16: 쌤앤파커스 | E16: 2013년 05월 | F16: 18000 | G16: 16200 | H16: 8691 | I16: 81 | J16: 9.2

Sheet 기타_출판사
A1: 순위 | B1: 도서명 | C1: 저자 | D1: 출판사 | E1: 출판일 | F1: 정가 | G1: 할인가 | H1: 판매지수 | I1: 리뷰건수 | J1: 평점 | K1: 태그
A2: 1 | B2: 나의 첫 번째 부동산 교과서 | C2: 송희구 | D2: 서삼독 | E2: 2026년 06월 | F2: 23000 | G2: 20700 | H2: 168537 | I2: 44 | J2: 9.3 | K2: #부동산투자, #부동산전망, #부동산공부, #부동산재테크, #부동산투자방법
A3: 2 | B3: 부의 갈림길 | C3: 오건영 | D3: 포레스트북스 | E3: 2026년 06월 | F3: 27000 | G3: 24300 | H3: 155631 | I3: 61 | J3: 9.9 | K3: #이달의주목신간, #돈구경시켜드릴게, #부자되는법, #성공하고싶다면, #돈이란무엇인가
A4: 3 | B4: 주식 투자를 잘한다는 것 | C4: 육과장 | D4: 노티스 | E4: 2026년 04월 | F4: 22000 | G4: 19800 | H4: 109503 | I4: 87 | J4: 9.8 | K4: #성장주찾기, #그래제본소, #주식투자입문, #주식투자, #주식초보
A5: 4 | B5: 독하게 돈 공부 | C5: 박소연 | D5: 메이븐 | E5: 2026년 07월 | F5: 23000 | G5: 20700 | H5: 4878 | I5: 1 | J5: 8
A6: 5 | B6: 박곰희 연금 부자 수업 | C6: 박곰희 | D6: 인플루엔셜 | E6: 2025년 06월 | F6: 21000 | G6: 18900 | H6: 563742 | I6: 490 | J6: 9.7 | K6: #은퇴준비, #경제적자유, #똑똑하게투자하기, #노후대비
A7: 7 | B7: 돈의 심리학 (50만 부 기념 뉴 에디션) | C7: 모건 하우절 저/이지연 역 | D7: 인플루엔셜 | E7: 2026년 01월 | F7: 24800 | G7: 22320 | H7: 139710 | I7: 1317 | J7: 9.4 | K7: #투자전략, #주식초보, #주식투자입문, #주식투자, #부자되는법
A8: 9 | B8: 사라지는 돈, 살아남는 돈, 불어나는 돈 | C8: 김효진 | D8: 페이지2북스 | E8: 2026년 07월 | F8: 21000 | G8: 18900 | H8: 17871 | I8: 4 | J8: 10
A9: 10 | B9: 복합불황 2027~2030 | C9: 박홍기 | D9: 바른북스 | E9: 2026년 06월 | F9: 24000 | G9: 21600 | H9: 49995 | I9: 35 | J9: 10
A10: 11 | B10: 불변의 법칙 | C10: 모건 하우절 저/이수경 역 | D10: 서삼독 | E10: 2024년 02월 | F10: 25000 | G10: 22500 | H10: 94503 | I10: 781 | J10: 9.5 | K10: #2026_리딩런_마라톤코스추천, #올해의책, #부자되는법, #부자만들기, #돈좀벌어보자
A11: 12 | B11: 라오어의 미국주식 무한매수법 | C11: 라오어 | D11: 알키 | E11: 2021년 06월 | F11: 16000 | G11: 14400 | H11: 94869 | I11: 209 | J11: 9 | K11: #미국주식, #크레마클럽에있어요
A12: 13 | B12: 부富의 알고리즘 | C12: 염규남 | D12: 북랩 | E12: 2026년 07월 | F12: 20000 | G12: 18000 | H12: 1542 | I12: 0 | J12: 0
A13: 14 | B13: 라오어의 미국주식 밸류 리밸런싱 | C13: 라오어 | D13: 알키 | E13: 2022년 08월 | F13: 18000 | G13: 16200 | H13: 80004 | I13: 141 | J13: 8.6 | K13: #크레마클럽에있어요
A14: 15 | B14: 주식은 미국의 전략을 따라 움직인다 | C14: 소현철 | D14: 황금부엉이 | E14: 2026년 07월 | F14: 24000 | G14: 21600 | H14: 3240 | I14: 2 | J14: 10
A15: 16 | B15: 딴딴한 투자를 위한 주식투자 교과서 | C15: 정규준 | D15: 애덤스미스 | E15: 2026년 03월 | F15: 25000 | G15: 22500 | H15: 80412 | I15: 104 | J15: 9.7 | K15: #투자심리, #개미일기, #주식투자입문, #슈퍼개미
A16: 17 | B16: 박태웅의 AI 강의 2026 | C16: 박태웅 | D16: 한빛비즈 | E16: 2026년 03월 | F16: 23000 | G16: 20700 | H16: 77622 | I16: 98 | J16: 9.6 | K16: #경제이야기, #경제전망, #내인생첫경제공부, #인공지능, #인공지능교육
A17: 18 | B17: 돈의 방정식 | C17: 모건 하우절 저/박영준 역 | D17: 서삼독 | E17: 2026년 01월 | F17: 28000 | G17: 25200 | H17: 142869 | I17: 204 | J17: 9.3 | K17: #2026_SERICEO_휴가철추천도서, #2026_리딩런_마라톤코스추천, #돈이란무엇인가, #돈관념, #돈을아십니까
A18: 19 | B18: 돈미새 | C18: 정윤진 | D18: 모티브 | E18: 2025년 02월 | F18: 18800 | G18: 16920 | H18: 2184 | I18: 72 | J18: 9.3
A19: 20 | B19: 천만 원으로 시작해 매달 500만 원 받는 ETF 월배당머신 | C19: 평온, 김지형 | D19: 이나우스북스 | E19: 2026년 05월 | F19: 23000 | G19: 20700 | H19: 39567 | I19: 121 | J19: 9.9 | K19: #ETF투자, #주식고수
A20: 21 | B20: AI, 신의 탄생 인간의 종말 | C20: 엘리에저 유드코스키, 네이트 소아레스 저/고영훈 역 | D20: 상상스퀘어 | E20: 2026년 04월 | F20: 22000 | G20: 19800 | H20: 52545 | I20: 33 | J20: 9.7 | K20: #2026_SERICEO_휴가철추천도서, #디지털경제, #세계경제, #경제이야기, #경제전망
A21: 22 | B21: 강남 아파트는 못 샀어도, 좋은 주식은 살 수 있다 | C21: 채부심(채상욱) | D21: 커넥티드그라운드 | E21: 2026년 06월 | F21: 22000 | G21: 19800 | H21: 42096 | I21: 3 | J21: 10
A22: 23 | B22: 주도주 사이클 절대 법칙 | C22: 한규범 | D22: 부키 | E22: 2026년 05월 | F22: 22000 | G22: 19800 | H22: 36765 | I22: 39 | J22: 9.9 | K22: #성장주찾기, #주식투자입문, #주식투자, #주식초보, #주식고수
A23: 24 | B23: 정프로의 한없이 가벼운 경제 상식 | C23: 정영진 | D23: 저녁달 | E23: 2026년 06월 | F23: 20000 | G23: 18000 | H23: 10050 | I23: 3 | J23: 10
A24: 25 | B24: 슈퍼개미 이정윤의 성장주 집중 투자 | C24: 이정윤 | D24: 베가북스 | E24: 2026년 06월 | F24: 25000 | G24: 22500 | H24: 88428 | I24: 19 | J24: 10 | K24: #성장주찾기, #똑똑하게투자하기, #주식매매법, #부자되는법, #주식투자
A25: 26 | B25: 자본주의 | C25: EBS 〈자본주의〉제작팀, 정지은, 고희정 저/EBS MEDIA 기획 | D25: 가나출판사 | E25: 2013년 09월 | F25: 22000 | G25: 19800 | H25: 88518 | I25: 1042 | J25: 9.5 | K25: #크레마클럽에있어요, #북클러버의선택, #금융문맹탈출
A26: 30 | B26: 3줄의 글로 수익을 만드는 스레드 운영법 | C26: 이동영 | D26: 한빛미디어 | E26: 2025년 10월 | F26: 20000 | G26: 18000 | H26: 13386 | I26: 39 | J26: 9.6
A27: 31 | B27: 돈, 뜨겁게 사랑하고 차갑게 다루어라 | C27: 앙드레 코스톨라니 저/한윤진 역 | D27: 미래의창 | E27: 2023년 09월 | F27: 15000 | G27: 13500 | H27: 38145 | I27: 139 | J27: 9.4
A28: 32 | B28: 최고의 주식 최적의 타이밍 | C28: 윌리엄 J. 오닐 | D28: 굿모닝북스 | E28: 2012년 06월 | F28: 19800 | G28: 17820 | H28: 27168 | I28: 190 | J28: 9.3
A29: 33 | B29: 주식투자 불패의 법칙 | C29: 조진표 | D29: 오아시스 | E29: 2026년 07월 | F29: 21000 | G29: 18900 | H29: 18816 | I29: 6 | J29: 10
A30: 34 | B30: 평생 월 500만 원 받는 월배당 ETF | C30: 배당의만장 | D30: 노티스 | E30: 2026년 03월 | F30: 23000 | G30: 20700 | H30: 49095 | I30: 50 | J30: 9.9 | K30: #투자트렌드, #투자가이드, #똑똑하게투자하기, #투자전략, #ETF투자
A31: 35 | B31: 손자병법 | C31: 손자 저/소준섭 역 | D31: 현대지성 | E31: 2025년 10월 | F31: 13000 | G31: 11700 | H31: 147624 | I31: 277 | J31: 9.7 | K31: #위기대응, #동양고전, #리더십, #동양철학, #불멸의고전
A32: 36 | B32: 제로 투 원 (10주년 기념판) | C32: 피터 틸, 블레이크 매스터스 저/이지연 역 | D32: 한국경제신문사(한경비피) | E32: 2025년 04월 | F32: 18000 | G32: 16200 | H32: 82614 | I32: 205 | J32: 9.7 | K32: #미래경영, #경영철학, #경영전략
A33: 37 | B33: 1억부터는 포트폴리오다 | C33: 신환종 | D33: 에프엔미디어 | E33: 2026년 07월 | F33: 25000 | G33: 22500 | H33: 5604 | I33: 2 | J33: 10
A34: 38 | B34: 나는 성장주 투자로 40에 은퇴했다 | C34: 파돌댁 | D34: 체인지업 | E34: 2026년 07월 | F34: 23000 | G34: 20700 | H34: 4692 | I34: 13 | J34: 10
A35: 39 | B35: 캔들차트 하나로 끝내는 추세추종 투자 | C35: 성승현 | D35: 포르체 | E35: 2026년 01월 | F35: 25000 | G35: 22500 | H35: 96099 | I35: 70 | J35: 8.7 | K35: #차트공부, #주식차트, #주식투자, #주식매매법
A36: 40 | B36: 자본주의 시대에서 살아남기 위한 최소한의 경제 공부 | C36: 백억남(김욱현) | D36: 하이스트 | E36: 2025년 12월 | F36: 28000 | G36: 25200 | H36: 173718 | I36: 89 | J36: 9.7 | K36: #내인생첫경제공부
A37: 41 | B37: 대형주 추세추종 투자법칙 | C37: 이종호(전황) | D37: 사피엔테스 | E37: 2025년 11월 | F37: 22000 | G37: 19800 | H37: 159285 | I37: 137 | J37: 9.5 | K37: #성공투자서, #주식매매법
A38: 42 | B38: 부의 인문학 (20만부 기념 개정증보판) | C38: 브라운스톤(우석) | D38: 오픈마인드 | E38: 2022년 03월 | F38: 17000 | G38: 15300 | H38: 58884 | I38: 289 | J38: 9 | K38: #크레마클럽에있어요, #미래전략, #부자비법, #똑똑하게투자하기
A39: 44 | B39: 돈의 속성 400쇄 리커버 | C39: 김승호 | D39: 스노우폭스북스 | E39: 2020년 06월 | F39: 17800 | G39: 16020 | H39: 133641 | I39: 1883 | J39: 9.5 | K39: #돈관리의모든것, #주식투자입문, #주식초보, #다시보는2020, #올해의책
A40: 45 | B40: 염승환·김익환의 대한민국 주식투자 지도 | C40: 염승환, 김익환 | D40: 메이트북스 | E40: 2026년 07월 | F40: 20000 | G40: 18000 | H40: 3594 | I40: 0 | J40: 0
...
